Workbook

Sheet Notes
A1: Benchmark: build/tree_benchmark, compiled with g++ 13.3.0 -std=c++20 -O2 -DNDEBUG
A2: Machine: Liang Zhou's laptop, Ubuntu 24.04 (WSL), pinned with taskset -c 2
A3: Source: results_o2/run_1.txt to run_11.txt (nanobench output, parsed unchanged)
A4: Median sheet: MEDIAN of ns/op over the 11 run sheets (formulas)
A5: Ratios sheet: computed from the Median sheet at n = 262144 (2^18)
A6: Unstable = nanobench flagged the row (err% high); insert/erase rows time one pass of n keys, so they are noisier

Sheet Median
A1: Operation | B1: Structure | C1: Order | D1: n | E1: Median ns/op | F1: Min ns/op | G1: Max ns/op | H1: Unstable runs
A2: find | B2: map | C2: sorted | D2: 4096 | E2: =MEDIAN('Run 1'!E2,'Run 2'!E2,'Run 3'!E2,'Run 4'!E2,'Run 5'!E2,'Run 6'!E2,'Run 7'!E2,'Run 8'!E2,'Run 9'!E2,'Run 10'!E2,'Run 11'!E2) -> 47.04 | F2: =MIN('Run 1'!E2,'Run 2'!E2,'Run 3'!E2,'Run 4'!E2,'Run 5'!E2,'Run 6'!E2,'Run 7'!E2,'Run 8'!E2,'Run 9'!E2,'Run 10'!E2,'Run 11'!E2) -> 45.89 | G2: =MAX('Run 1'!E2,'Run 2'!E2,'Run 3'!E2,'Run 4'!E2,'Run 5'!E2,'Run 6'!E2,'Run 7'!E2,'Run 8'!E2,'Run 9'!E2,'Run 10'!E2,'Run 11'!E2) -> 48.92 | H2: =COUNTIF('Run 1'!I2,"Yes")+COUNTIF('Run 2'!I2,"Yes")+COUNTIF('Run 3'!I2,"Yes")+COUNTIF('Run 4'!I2,"Yes")+COUNTIF('Run 5'!I2,"Yes")+COUNTIF('Run 6'!I2,"Yes")+COUNTIF('Run 7'!I2,"Yes")+COUNTIF('Run 8'!I2,"Yes")+COUNTIF('Run 9'!I2,"Yes")+COUNTIF('Run 10'!I2,"Yes")+COUNTIF('Run 11'!I2,"Yes") -> 0
A3: find | B3: map | C3: random | D3: 4096 | E3: =MEDIAN('Run 1'!E3,'Run 2'!E3,'Run 3'!E3,'Run 4'!E3,'Run 5'!E3,'Run 6'!E3,'Run 7'!E3,'Run 8'!E3,'Run 9'!E3,'Run 10'!E3,'Run 11'!E3) -> 41.12 | F3: =MIN('Run 1'!E3,'Run 2'!E3,'Run 3'!E3,'Run 4'!E3,'Run 5'!E3,'Run 6'!E3,'Run 7'!E3,'Run 8'!E3,'Run 9'!E3,'Run 10'!E3,'Run 11'!E3) -> 40.27 | G3: =MAX('Run 1'!E3,'Run 2'!E3,'Run 3'!E3,'Run 4'!E3,'Run 5'!E3,'Run 6'!E3,'Run 7'!E3,'Run 8'!E3,'Run 9'!E3,'Run 10'!E3,'Run 11'!E3) -> 41.84 | H3: =COUNTIF('Run 1'!I3,"Yes")+COUNTIF('Run 2'!I3,"Yes")+COUNTIF('Run 3'!I3,"Yes")+COUNTIF('Run 4'!I3,"Yes")+COUNTIF('Run 5'!I3,"Yes")+COUNTIF('Run 6'!I3,"Yes")+COUNTIF('Run 7'!I3,"Yes")+COUNTIF('Run 8'!I3,"Yes")+COUNTIF('Run 9'!I3,"Yes")+COUNTIF('Run 10'!I3,"Yes")+COUNTIF('Run 11'!I3,"Yes") -> 0
A4: find | B4: rb | C4: sorted | D4: 4096 | E4: =MEDIAN('Run 1'!E4,'Run 2'!E4,'Run 3'!E4,'Run 4'!E4,'Run 5'!E4,'Run 6'!E4,'Run 7'!E4,'Run 8'!E4,'Run 9'!E4,'Run 10'!E4,'Run 11'!E4) -> 14.16 | F4: =MIN('Run 1'!E4,'Run 2'!E4,'Run 3'!E4,'Run 4'!E4,'Run 5'!E4,'Run 6'!E4,'Run 7'!E4,'Run 8'!E4,'Run 9'!E4,'Run 10'!E4,'Run 11'!E4) -> 13.03 | G4: =MAX('Run 1'!E4,'Run 2'!E4,'Run 3'!E4,'Run 4'!E4,'Run 5'!E4,'Run 6'!E4,'Run 7'!E4,'Run 8'!E4,'Run 9'!E4,'Run 10'!E4,'Run 11'!E4) -> 14.86 | H4: =COUNTIF('Run 1'!I4,"Yes")+COUNTIF('Run 2'!I4,"Yes")+COUNTIF('Run 3'!I4,"Yes")+COUNTIF('Run 4'!I4,"Yes")+COUNTIF('Run 5'!I4,"Yes")+COUNTIF('Run 6'!I4,"Yes")+COUNTIF('Run 7'!I4,"Yes")+COUNTIF('Run 8'!I4,"Yes")+COUNTIF('Run 9'!I4,"Yes")+COUNTIF('Run 10'!I4,"Yes")+COUNTIF('Run 11'!I4,"Yes") -> 1
A5: find | B5: rb | C5: random | D5: 4096 | E5: =MEDIAN('Run 1'!E5,'Run 2'!E5,'Run 3'!E5,'Run 4'!E5,'Run 5'!E5,'Run 6'!E5,'Run 7'!E5,'Run 8'!E5,'Run 9'!E5,'Run 10'!E5,'Run 11'!E5) -> 12.95 | F5: =MIN('Run 1'!E5,'Run 2'!E5,'Run 3'!E5,'Run 4'!E5,'Run 5'!E5,'Run 6'!E5,'Run 7'!E5,'Run 8'!E5,'Run 9'!E5,'Run 10'!E5,'Run 11'!E5) -> 11.47 | G5: =MAX('Run 1'!E5,'Run 2'!E5,'Run 3'!E5,'Run 4'!E5,'Run 5'!E5,'Run 6'!E5,'Run 7'!E5,'Run 8'!E5,'Run 9'!E5,'Run 10'!E5,'Run 11'!E5) -> 13.66 | H5: =COUNTIF('Run 1'!I5,"Yes")+COUNTIF('Run 2'!I5,"Yes")+COUNTIF('Run 3'!I5,"Yes")+COUNTIF('Run 4'!I5,"Yes")+COUNTIF('Run 5'!I5,"Yes")+COUNTIF('Run 6'!I5,"Yes")+COUNTIF('Run 7'!I5,"Yes")+COUNTIF('Run 8'!I5,"Yes")+COUNTIF('Run 9'!I5,"Yes")+COUNTIF('Run 10'!I5,"Yes")+COUNTIF('Run 11'!I5,"Yes") -> 0
A6: find | B6: avl | C6: sorted | D6: 4096 | E6: =MEDIAN('Run 1'!E6,'Run 2'!E6,'Run 3'!E6,'Run 4'!E6,'Run 5'!E6,'Run 6'!E6,'Run 7'!E6,'Run 8'!E6,'Run 9'!E6,'Run 10'!E6,'Run 11'!E6) -> 9.65 | F6: =MIN('Run 1'!E6,'Run 2'!E6,'Run 3'!E6,'Run 4'!E6,'Run 5'!E6,'Run 6'!E6,'Run 7'!E6,'Run 8'!E6,'Run 9'!E6,'Run 10'!E6,'Run 11'!E6) -> 9.36 | G6: =MAX('Run 1'!E6,'Run 2'!E6,'Run 3'!E6,'Run 4'!E6,'Run 5'!E6,'Run 6'!E6,'Run 7'!E6,'Run 8'!E6,'Run 9'!E6,'Run 10'!E6,'Run 11'!E6) -> 9.95 | H6: =COUNTIF('Run 1'!I6,"Yes")+COUNTIF('Run 2'!I6,"Yes")+COUNTIF('Run 3'!I6,"Yes")+COUNTIF('Run 4'!I6,"Yes")+COUNTIF('Run 5'!I6,"Yes")+COUNTIF('Run 6'!I6,"Yes")+COUNTIF('Run 7'!I6,"Yes")+COUNTIF('Run 8'!I6,"Yes")+COUNTIF('Run 9'!I6,"Yes")+COUNTIF('Run 10'!I6,"Yes")+COUNTIF('Run 11'!I6,"Yes") -> 0
A7: find | B7: avl | C7: random | D7: 4096 | E7: =MEDIAN('Run 1'!E7,'Run 2'!E7,'Run 3'!E7,'Run 4'!E7,'Run 5'!E7,'Run 6'!E7,'Run 7'!E7,'Run 8'!E7,'Run 9'!E7,'Run 10'!E7,'Run 11'!E7) -> 11.74 | F7: =MIN('Run 1'!E7,'Run 2'!E7,'Run 3'!E7,'Run 4'!E7,'Run 5'!E7,'Run 6'!E7,'Run 7'!E7,'Run 8'!E7,'Run 9'!E7,'Run 10'!E7,'Run 11'!E7) -> 11.24 | G7: =MAX('Run 1'!E7,'Run 2'!E7,'Run 3'!E7,'Run 4'!E7,'Run 5'!E7,'Run 6'!E7,'Run 7'!E7,'Run 8'!E7,'Run 9'!E7,'Run 10'!E7,'Run 11'!E7) -> 12.13 | H7: =COUNTIF('Run 1'!I7,"Yes")+COUNTIF('Run 2'!I7,"Yes")+COUNTIF('Run 3'!I7,"Yes")+COUNTIF('Run 4'!I7,"Yes")+COUNTIF('Run 5'!I7,"Yes")+COUNTIF('Run 6'!I7,"Yes")+COUNTIF('Run 7'!I7,"Yes")+COUNTIF('Run 8'!I7,"Yes")+COUNTIF('Run 9'!I7,"Yes")+COUNTIF('Run 10'!I7,"Yes")+COUNTIF('Run 11'!I7,"Yes") -> 0
A8: find | B8: map | C8: sorted | D8: 16384 | E8: =MEDIAN('Run 1'!E8,'Run 2'!E8,'Run 3'!E8,'Run 4'!E8,'Run 5'!E8,'Run 6'!E8,'Run 7'!E8,'Run 8'!E8,'Run 9'!E8,'Run 10'!E8,'Run 11'!E8) -> 66.79 | F8: =MIN('Run 1'!E8,'Run 2'!E8,'Run 3'!E8,'Run 4'!E8,'Run 5'!E8,'Run 6'!E8,'Run 7'!E8,'Run 8'!E8,'Run 9'!E8,'Run 10'!E8,'Run 11'!E8) -> 65.18 | G8: =MAX('Run 1'!E8,'Run 2'!E8,'Run 3'!E8,'Run 4'!E8,'Run 5'!E8,'Run 6'!E8,'Run 7'!E8,'Run 8'!E8,'Run 9'!E8,'Run 10'!E8,'Run 11'!E8) -> 67.68 | H8: =COUNTIF('Run 1'!I8,"Yes")+COUNTIF('Run 2'!I8,"Yes")+COUNTIF('Run 3'!I8,"Yes")+COUNTIF('Run 4'!I8,"Yes")+COUNTIF('Run 5'!I8,"Yes")+COUNTIF('Run 6'!I8,"Yes")+COUNTIF('Run 7'!I8,"Yes")+COUNTIF('Run 8'!I8,"Yes")+COUNTIF('Run 9'!I8,"Yes")+COUNTIF('Run 10'!I8,"Yes")+COUNTIF('Run 11'!I8,"Yes") -> 0
A9: find | B9: map | C9: random | D9: 16384 | E9: =MEDIAN('Run 1'!E9,'Run 2'!E9,'Run 3'!E9,'Run 4'!E9,'Run 5'!E9,'Run 6'!E9,'Run 7'!E9,'Run 8'!E9,'Run 9'!E9,'Run 10'!E9,'Run 11'!E9) -> 59.57 | F9: =MIN('Run 1'!E9,'Run 2'!E9,'Run 3'!E9,'Run 4'!E9,'Run 5'!E9,'Run 6'!E9,'Run 7'!E9,'Run 8'!E9,'Run 9'!E9,'Run 10'!E9,'Run 11'!E9) -> 58.66 | G9: =MAX('Run 1'!E9,'Run 2'!E9,'Run 3'!E9,'Run 4'!E9,'Run 5'!E9,'Run 6'!E9,'Run 7'!E9,'Run 8'!E9,'Run 9'!E9,'Run 10'!E9,'Run 11'!E9) -> 60.31 | H9: =COUNTIF('Run 1'!I9,"Yes")+COUNTIF('Run 2'!I9,"Yes")+COUNTIF('Run 3'!I9,"Yes")+COUNTIF('Run 4'!I9,"Yes")+COUNTIF('Run 5'!I9,"Yes")+COUNTIF('Run 6'!I9,"Yes")+COUNTIF('Run 7'!I9,"Yes")+COUNTIF('Run 8'!I9,"Yes")+COUNTIF('Run 9'!I9,"Yes")+COUNTIF('Run 10'!I9,"Yes")+COUNTIF('Run 11'!I9,"Yes") -> 0
A10: find | B10: rb | C10: sorted | D10: 16384 | E10: =MEDIAN('Run 1'!E10,'Run 2'!E10,'Run 3'!E10,'Run 4'!E10,'Run 5'!E10,'Run 6'!E10,'Run 7'!E10,'Run 8'!E10,'Run 9'!E10,'Run 10'!E10,'Run 11'!E10) -> 26.8 | F10: =MIN('Run 1'!E10,'Run 2'!E10,'Run 3'!E10,'Run 4'!E10,'Run 5'!E10,'Run 6'!E10,'Run 7'!E10,'Run 8'!E10,'Run 9'!E10,'Run 10'!E10,'Run 11'!E10) -> 26.01 | G10: =MAX('Run 1'!E10,'Run 2'!E10,'Run 3'!E10,'Run 4'!E10,'Run 5'!E10,'Run 6'!E10,'Run 7'!E10,'Run 8'!E10,'Run 9'!E10,'Run 10'!E10,'Run 11'!E10) -> 27.04 | H10: =COUNTIF('Run 1'!I10,"Yes")+COUNTIF('Run 2'!I10,"Yes")+COUNTIF('Run 3'!I10,"Yes")+COUNTIF('Run 4'!I10,"Yes")+COUNTIF('Run 5'!I10,"Yes")+COUNTIF('Run 6'!I10,"Yes")+COUNTIF('Run 7'!I10,"Yes")+COUNTIF('Run 8'!I10,"Yes")+COUNTIF('Run 9'!I10,"Yes")+COUNTIF('Run 10'!I10,"Yes")+COUNTIF('Run 11'!I10,"Yes") -> 0
A11: find | B11: rb | C11: random | D11: 16384 | E11: =MEDIAN('Run 1'!E11,'Run 2'!E11,'Run 3'!E11,'Run 4'!E11,'Run 5'!E11,'Run 6'!E11,'Run 7'!E11,'Run 8'!E11,'Run 9'!E11,'Run 10'!E11,'Run 11'!E11) -> 24.21 | F11: =MIN('Run 1'!E11,'Run 2'!E11,'Run 3'!E11,'Run 4'!E11,'Run 5'!E11,'Run 6'!E11,'Run 7'!E11,'Run 8'!E11,'Run 9'!E11,'Run 10'!E11,'Run 11'!E11) -> 23.67 | G11: =MAX('Run 1'!E11,'Run 2'!E11,'Run 3'!E11,'Run 4'!E11,'Run 5'!E11,'Run 6'!E11,'Run 7'!E11,'Run 8'!E11,'Run 9'!E11,'Run 10'!E11,'Run 11'!E11) -> 25.06 | H11: =COUNTIF('Run 1'!I11,"Yes")+COUNTIF('Run 2'!I11,"Yes")+COUNTIF('Run 3'!I11,"Yes")+COUNTIF('Run 4'!I11,"Yes")+COUNTIF('Run 5'!I11,"Yes")+COUNTIF('Run 6'!I11,"Yes")+COUNTIF('Run 7'!I11,"Yes")+COUNTIF('Run 8'!I11,"Yes")+COUNTIF('Run 9'!I11,"Yes")+COUNTIF('Run 10'!I11,"Yes")+COUNTIF('Run 11'!I11,"Yes") -> 0
A12: find | B12: avl | C12: sorted | D12: 16384 | E12: =MEDIAN('Run 1'!E12,'Run 2'!E12,'Run 3'!E12,'Run 4'!E12,'Run 5'!E12,'Run 6'!E12,'Run 7'!E12,'Run 8'!E12,'Run 9'!E12,'Run 10'!E12,'Run 11'!E12) -> 18.18 | F12: =MIN('Run 1'!E12,'Run 2'!E12,'Run 3'!E12,'Run 4'!E12,'Run 5'!E12,'Run 6'!E12,'Run 7'!E12,'Run 8'!E12,'Run 9'!E12,'Run 10'!E12,'Run 11'!E12) -> 17.77 | G12: =MAX('Run 1'!E12,'Run 2'!E12,'Run 3'!E12,'Run 4'!E12,'Run 5'!E12,'Run 6'!E12,'Run 7'!E12,'Run 8'!E12,'Run 9'!E12,'Run 10'!E12,'Run 11'!E12) -> 18.87 | H12: =COUNTIF('Run 1'!I12,"Yes")+COUNTIF('Run 2'!I12,"Yes")+COUNTIF('Run 3'!I12,"Yes")+COUNTIF('Run 4'!I12,"Yes")+COUNTIF('Run 5'!I12,"Yes")+COUNTIF('Run 6'!I12,"Yes")+COUNTIF('Run 7'!I12,"Yes")+COUNTIF('Run 8'!I12,"Yes")+COUNTIF('Run 9'!I12,"Yes")+COUNTIF('Run 10'!I12,"Yes")+COUNTIF('Run 11'!I12,"Yes") -> 0
A13: find | B13: avl | C13: random | D13: 16384 | E13: =MEDIAN('Run 1'!E13,'Run 2'!E13,'Run 3'!E13,'Run 4'!E13,'Run 5'!E13,'Run 6'!E13,'Run 7'!E13,'Run 8'!E13,'Run 9'!E13,'Run 10'!E13,'Run 11'!E13) -> 21.43 | F13: =MIN('Run 1'!E13,'Run 2'!E13,'Run 3'!E13,'Run 4'!E13,'Run 5'!E13,'Run 6'!E13,'Run 7'!E13,'Run 8'!E13,'Run 9'!E13,'Run 10'!E13,'Run 11'!E13) -> 20.71 | G13: =MAX('Run 1'!E13,'Run 2'!E13,'Run 3'!E13,'Run 4'!E13,'Run 5'!E13,'Run 6'!E13,'Run 7'!E13,'Run 8'!E13,'Run 9'!E13,'Run 10'!E13,'Run 11'!E13) -> 22.19 | H13: =COUNTIF('Run 1'!I13,"Yes")+COUNTIF('Run 2'!I13,"Yes")+COUNTIF('Run 3'!I13,"Yes")+COUNTIF('Run 4'!I13,"Yes")+COUNTIF('Run 5'!I13,"Yes")+COUNTIF('Run 6'!I13,"Yes")+COUNTIF('Run 7'!I13,"Yes")+COUNTIF('Run 8'!I13,"Yes")+COUNTIF('Run 9'!I13,"Yes")+COUNTIF('Run 10'!I13,"Yes")+COUNTIF('Run 11'!I13,"Yes") -> 0
... A73: erase | B73: avl | C73: random | D73: 262144 | E73: =MEDIAN('Run 1'!E73,'Run 2'!E73,'Run 3'!E73,'Run 4'!E73,'Run 5'!E73,'Run 6'!E73,'Run 7'!E73,'Run 8'!E73,'Run 9'!E73,'Run 10'!E73,'Run 11'!E73) -> 212.49 | F73: =MIN('Run 1'!E73,'Run 2'!E73,'Run 3'!E73,'Run 4'!E73,'Run 5'!E73,'Run 6'!E73,'Run 7'!E73,'Run 8'!E73,'Run 9'!E73,'Run 10'!E73,'Run 11'!E73) -> 208.07 | G73: =MAX('Run 1'!E73,'Run 2'!E73,'Run 3'!E73,'Run 4'!E73,'Run 5'!E73,'Run 6'!E73,'Run 7'!E73,'Run 8'!E73,'Run 9'!E73,'Run 10'!E73,'Run 11'!E73) -> 224.88 | H73: =COUNTIF('Run 1'!I73,"Yes")+COUNTIF('Run 2'!I73,"Yes")+COUNTIF('Run 3'!I73,"Yes")+COUNTIF('Run 4'!I73,"Yes")+COUNTIF('Run 5'!I73,"Yes")+COUNTIF('Run 6'!I73,"Yes")+COUNTIF('Run 7'!I73,"Yes")+COUNTIF('Run 8'!I73,"Yes")+COUNTIF('Run 9'!I73,"Yes")+COUNTIF('Run 10'!I73,"Yes")+COUNTIF('Run 11'!I73,"Yes") -> 2

Sheet Runtime Charts
A1: n | B1: AVL | C1: Red Black | D1: MapBaseLine | J1: n | K1: AVL | L1: Red Black | M1: MapBaseLine
A2: 4096 | B2: 9.65 | C2: 14.16 | D2: 47.04 | J2: 4096 | K2: 11.74 | L2: 12.95 | M2: 41.12
A3: 16384 | B3: 18.18 | C3: 26.8 | D3: 66.79 | J3: 16384 | K3: 21.43 | L3: 24.21 | M3: 59.57
A4: 65536 | B4: 26.59 | C4: 40.48 | D4: 100.09 | J4: 65536 | K4: 29.97 | L4: 36.62 | M4: 95.45
A5: 262144 | B5: 49.25 | C5: 78.5 | D5: 183.11 | J5: 262144 | K5: 51.48 | L5: 73.82 | M5: 180.33
A25: n | B25: AVL | C25: Red Black | D25: MapBaseLine | J25: n | K25: AVL | L25: Red Black | M25: MapBaseLine
A26: 4096 | B26: 25.27 | C26: 22.82 | D26: 19.56 | J26: 4096 | K26: 60.77 | L26: 37.32 | M26: 55.58
A27: 16384 | B27: 30.03 | C27: 29.15 | D27: 23.64 | J27: 16384 | K27: 78.87 | L27: 57.9 | M27: 70.35
A28: 65536 | B28: 33.54 | C28: 60.8 | D28: 57.76 | J28: 65536 | K28: 119.48 | L28: 102 | M28: 94.51
A29: 262144 | B29: 43.99 | C29: 83.27 | D29: 76.77 | J29: 262144 | K29: 189.16 | L29: 190.87 | M29: 149.7
A49: n | B49: AVL | C49: Red Black | D49: MapBaseLine | J49: n | K49: AVL | L49: Red Black | M49: MapBaseLine
A50: 4096 | B50: 19.93 | C50: 14.8 | D50: 17.14 | J50: 4096 | K50: 62.55 | L50: 38.55 | M50: 58.95
A51: 16384 | B51: 23.73 | C51: 17.18 | D51: 18.85 | J51: 16384 | K51: 81.1 | L51: 54.18 | M51: 82.23
A52: 65536 | B52: 28.05 | C52: 33.44 | D52: 19.62 | J52: 65536 | K52: 125.8 | L52: 96.64 | M52: 122.61
A53: 262144 | B53: 32.63 | C53: 39.73 | D53: 25.99 | J53: 262144 | K53: 212.49 | L53: 175.54 | M53: 206.6

Sheet Ratios
A1: AVL/RB time ratio at n = 262144 (above 1 = AVL slower)
A2: Random insertion | B2: =Median!E49/Median!E47 -> 0.99104102
A3: Random deletion | B3: =Median!E73/Median!E71 -> 1.2104933
A4: Sorted insertion | B4: =Median!E48/Median!E46 -> 0.52828149
A5: Sorted deletion | B5: =Median!E72/Median!E70 -> 0.82129373
A6: Random find | B6: =Median!E25/Median!E23 -> 0.69737199
A7: Sorted find | B7: =Median!E24/Median!E22 -> 0.62738854
A9: Sorted-to-random speed ratio at n = 262144 (random time / sorted time; compare Brown Table 4)
A10: AVL insertion | B10: =Median!E49/Median!E48 -> 4.3000682
A11: AVL deletion | B11: =Median!E73/Median!E72 -> 6.5121054
A12: RB insertion | B12: =Median!E47/Median!E46 -> 2.2921821
A13: RB deletion | B13: =Median!E71/Median!E70 -> 4.4183237

Sheet Run 1
A1: Operation | B1: Structure | C1: Order | D1: n | E1: ns/op | F1: ops/s | G1: Err % | H1: Total (s) | I1: Unstable
A2: find | B2: map | C2: sorted | D2: 4096 | E2: 47.04 | F2: 21256808 | G2: 0.002 | H2: 0.11
A3: find | B3: map | C3: random | D3: 4096 | E3: 40.54 | F3: 24666120 | G3: 0.026 | H3: 0.1
A4: find | B4: rb | C4: sorted | D4: 4096 | E4: 13.69 | F4: 73039219 | G4: 0.004 | H4: 0.03
A5: find | B5: rb | C5: random | D5: 4096 | E5: 13.66 | F5: 73206040 | G5: 0.036 | H5: 0.03
A6: find | B6: avl | C6: sorted | D6: 4096 | E6: 9.46 | F6: 1.0574515e+08 | G6: 0.014 | H6: 0.02
A7: find | B7: avl | C7: random | D7: 4096 | E7: 11.94 | F7: 83748764 | G7: 0.011 | H7: 0.03
A8: find | B8: map | C8: sorted | D8: 16384 | E8: 67.19 | F8: 14883309 | G8: 0.015 | H8: 0.15
A9: find | B9: map | C9: random | D9: 16384 | E9: 60.06 | F9: 16651032 | G9: 0.01 | H9: 0.15
A10: find | B10: rb | C10: sorted | D10: 16384 | E10: 26.84 | F10: 37255987 | G10: 0.006 | H10: 0.07
A11: find | B11: rb | C11: random | D11: 16384 | E11: 24.38 | F11: 41012302 | G11: 0.005 | H11: 0.06
A12: find | B12: avl | C12: sorted | D12: 16384 | E12: 18.32 | F12: 54587027 | G12: 0.008 | H12: 0.04
A13: find | B13: avl | C13: random | D13: 16384 | E13: 21.36 | F13: 46825983 | G13: 0.006 | H13: 0.05
... A31: insert | B31: avl | C31: random | D31: 4096 | E31: 62.53 | F31: 15993128 | G31: 0.013 | H31: 0
A32: insert | B32: map | C32: sorted | D32: 16384 | E32: 23.31 | F32: 42899823 | G32: 0.067 | H32: 0 | I32: Yes
A33: insert | B33: map | C33: random | D33: 16384 | E33: 70.01 | F33: 14284319 | G33: 0.015 | H33: 0.01
A34: insert | B34: rb | C34: sorted | D34: 16384 | E34: 29.2 | F34: 34252002 | G34: 0.035 | H34: 0.01
A35: insert | B35: rb | C35: random | D35: 16384 | E35: 56.17 | F35: 17802639 | G35: 0.019 | H35: 0.01
A36: insert | B36: avl | C36: sorted | D36: 16384 | E36: 30.53 | F36: 32750708 | G36: 0.018 | H36: 0.01
A37: insert | B37: avl | C37: random | D37: 16384 | E37: 78.57 | F37: 12727414 | G37: 0.016 | H37: 0.01
A38: insert | B38: map | C38: sorted | D38: 65536 | E38: 58.35 | F38: 17138111 | G38: 0.026 | H38: 0.03
A39: insert | B39: map | C39: random | D39: 65536 | E39: 95.71 | F39: 10448616 | G39: 0.008 | H39: 0.07
A40: insert | B40: rb | C40: sorted | D40: 65536 | E40: 73.71 | F40: 13566210 | G40: 0.094 | H40: 0.04 | I40: Yes
A41: insert | B41: rb | C41: random | D41: 65536 | E41: 99.73 | F41: 10027506 | G41: 0.097 | H41: 0.07 | I41: Yes
A42: insert | B42: avl | C42: sorted | D42: 65536 | E42: 33.84 | F42: 29548632 | G42: 0.045 | H42: 0.04
A43: insert | B43: avl | C43: random | D43: 65536 | E43: 119.48 | F43: 8369390.3 | G43: 0.023 | H43: 0.09
A44: insert | B44: map | C44: sorted | D44: 262144 | E44: 73.88 | F44: 13536306 | G44: 0.046 | H44: 0.2
A45: insert | B45: map | C45: random | D45: 262144 | E45: 201.07 | F45: 4973460.2 | G45: 0.211 | H45: 0.57 | I45: Yes
A46: insert | B46: rb | C46: sorted | D46: 262144 | E46: 79.67 | F46: 12552103 | G46: 0.041 | H46: 0.23
A47: insert | B47: rb | C47: random | D47: 262144 | E47: 198.84 | F47: 5029138.4 | G47: 0.027 | H47: 0.57
A48: insert | B48: avl | C48: sorted | D48: 262144 | E48: 43.55 | F48: 22961347 | G48: 0.055 | H48: 0.23 | I48: Yes
A49: insert | B49: avl | C49: random | D49: 262144 | E49: 192.01 | F49: 5208144.8 | G49: 0.013 | H49: 0.55
A50: erase | B50: map | C50: sorted | D50: 4096 | E50: 16.91 | F50: 59132644 | G50: 0.024 | H50: 0
A51: erase | B51: map | C51: random | D51: 4096 | E51: 59.36 | F51: 16846331 | G51: 0.022 | H51: 0
A52: erase | B52: rb | C52: sorted | D52: 4096 | E52: 15.11 | F52: 66183005 | G52: 0.057 | H52: 0 | I52: Yes
A53: erase | B53: rb | C53: random | D53: 4096 | E53: 38.5 | F53: 25976662 | G53: 0.034 | H53: 0
A54: erase | B54: avl | C54: sorted | D54: 4096 | E54: 20.28 | F54: 49319687 | G54: 0.017 | H54: 0
A55: erase | B55: avl | C55: random | D55: 4096 | E55: 62.91 | F55: 15895191 | G55: 0.019 | H55: 0
A56: erase | B56: map | C56: sorted | D56: 16384 | E56: 17.93 | F56: 55786904 | G56: 0.038 | H56: 0
A57: erase | B57: map | C57: random | D57: 16384 | E57: 81.05 | F57: 12337433 | G57: 0.007 | H57: 0.01
...

Sheet Run 2
A1: Operation | B1: Structure | C1: Order | D1: n | E1: ns/op | F1: ops/s | G1: Err % | H1: Total (s) | I1: Unstable
A2: find | B2: map | C2: sorted | D2: 4096 | E2: 48.12 | F2: 20780841 | G2: 0.014 | H2: 0.12
A3: find | B3: map | C3: random | D3: 4096 | E3: 41.84 | F3: 23900467 | G3: 0.009 | H3: 0.1
A4: find | B4: rb | C4: sorted | D4: 4096 | E4: 14.16 | F4: 70602911 | G4: 0.012 | H4: 0.03
A5: find | B5: rb | C5: random | D5: 4096 | E5: 13.24 | F5: 75526516 | G5: 0.003 | H5: 0.03
A6: find | B6: avl | C6: sorted | D6: 4096 | E6: 9.73 | F6: 1.0274003e+08 | G6: 0.009 | H6: 0.02
A7: find | B7: avl | C7: random | D7: 4096 | E7: 11.74 | F7: 85210143 | G7: 0.012 | H7: 0.03
A8: find | B8: map | C8: sorted | D8: 16384 | E8: 65.91 | F8: 15172493 | G8: 0.006 | H8: 0.16
A9: find | B9: map | C9: random | D9: 16384 | E9: 58.84 | F9: 16996275 | G9: 0.007 | H9: 0.14
A10: find | B10: rb | C10: sorted | D10: 16384 | E10: 26.8 | F10: 37309004 | G10: 0.007 | H10: 0.06
A11: find | B11: rb | C11: random | D11: 16384 | E11: 24.22 | F11: 41290726 | G11: 0.011 | H11: 0.06
A12: find | B12: avl | C12: sorted | D12: 16384 | E12: 18.4 | F12: 54357283 | G12: 0.008 | H12: 0.04
A13: find | B13: avl | C13: random | D13: 16384 | E13: 21.75 | F13: 45983858 | G13: 0.018 | H13: 0.05
... A22: find | B22: rb | C22: sorted | D22: 262144 | E22: 79.43 | F22: 12589608 | G22: 0.007 | H22: 0.19
A23: find | B23: rb | C23: random | D23: 262144 | E23: 83.41 | F23: 11988439 | G23: 0.065 | H23: 0.2 | I23: Yes
A24: find | B24: avl | C24: sorted | D24: 262144 | E24: 49.84 | F24: 20063414 | G24: 0.007 | H24: 0.12
A25: find | B25: avl | C25: random | D25: 262144 | E25: 53.39 | F25: 18728652 | G25: 0.011 | H25: 0.13
A26: insert | B26: map | C26: sorted | D26: 4096 | E26: 19.49 | F26: 51303890 | G26: 0.052 | H26: 0 | I26: Yes
A27: insert | B27: map | C27: random | D27: 4096 | E27: 56.4 | F27: 17730143 | G27: 0.028 | H27: 0
A28: insert | B28: rb | C28: sorted | D28: 4096 | E28: 22.44 | F28: 44557094 | G28: 0.016 | H28: 0
A29: insert | B29: rb | C29: random | D29: 4096 | E29: 37.32 | F29: 26791905 | G29: 0.028 | H29: 0
A30: insert | B30: avl | C30: sorted | D30: 4096 | E30: 25.31 | F30: 39511889 | G30: 0.009 | H30: 0
A31: insert | B31: avl | C31: random | D31: 4096 | E31: 59.86 | F31: 16704390 | G31: 0.04 | H31: 0
A32: insert | B32: map | C32: sorted | D32: 16384 | E32: 24.17 | F32: 41370185 | G32: 0.066 | H32: 0 | I32: Yes
A33: insert | B33: map | C33: random | D33: 16384 | E33: 70.1 | F33: 14265452 | G33: 0.01 | H33: 0.01
A34: insert | B34: rb | C34: sorted | D34: 16384 | E34: 29.47 | F34: 33932074 | G34: 0.018 | H34: 0.01
A35: insert | B35: rb | C35: random | D35: 16384 | E35: 57.84 | F35: 17288281 | G35: 0.01 | H35: 0.01
A36: insert | B36: avl | C36: sorted | D36: 16384 | E36: 29.34 | F36: 34084337 | G36: 0.032 | H36: 0.01
A37: insert | B37: avl | C37: random | D37: 16384 | E37: 80.32 | F37: 12449432 | G37: 0.004 | H37: 0.01
A38: insert | B38: map | C38: sorted | D38: 65536 | E38: 57.99 | F38: 17243997 | G38: 0.258 | H38: 0.04 | I38: Yes
A39: insert | B39: map | C39: random | D39: 65536 | E39: 94.38 | F39: 10595600 | G39: 0.012 | H39: 0.07
A40: insert | B40: rb | C40: sorted | D40: 65536 | E40: 64.17 | F40: 15583592 | G40: 0.235 | H40: 0.04 | I40: Yes
A41: insert | B41: rb | C41: random | D41: 65536 | E41: 107.31 | F41: 9318801.5 | G41: 0.03 | H41: 0.07
A42: insert | B42: avl | C42: sorted | D42: 65536 | E42: 33.25 | F42: 30071655 | G42: 0.04 | H42: 0.04
A43: insert | B43: avl | C43: random | D43: 65536 | E43: 115.53 | F43: 8656132.1 | G43: 0.007 | H43: 0.08
A44: insert | B44: map | C44: sorted | D44: 262144 | E44: 89.54 | F44: 11167965 | G44: 0.07 | H44: 0.22 | I44: Yes
A45: insert | B45: map | C45: random | D45: 262144 | E45: 152.22 | F45: 6569364.3 | G45: 0.009 | H45: 0.44
A46: insert | B46: rb | C46: sorted | D46: 262144 | E46: 83.32 | F46: 12002325 | G46: 0.014 | H46: 0.23
A47: insert | B47: rb | C47: random | D47: 262144 | E47: 195.97 | F47: 5102773.2 | G47: 0.049 | H47: 0.57
A48: insert | B48: avl | C48: sorted | D48: 262144 | E48: 43.72 | F48: 22873966 | G48: 0.063 | H48: 0.22 | I48: Yes
...

Sheet Run 3
A1: Operation | B1: Structure | C1: Order | D1: n | E1: ns/op | F1: ops/s | G1: Err % | H1: Total (s) | I1: Unstable
A2: find | B2: map | C2: sorted | D2: 4096 | E2: 48.92 | F2: 20441470 | G2: 0.007 | H2: 0.12
A3: find | B3: map | C3: random | D3: 4096 | E3: 40.98 | F3: 24401519 | G3: 0.003 | H3: 0.1
A4: find | B4: rb | C4: sorted | D4: 4096 | E4: 14.61 | F4: 68452320 | G4: 0.116 | H4: 0.04 | I4: Yes
A5: find | B5: rb | C5: random | D5: 4096 | E5: 11.47 | F5: 87160268 | G5: 0.005 | H5: 0.03
A6: find | B6: avl | C6: sorted | D6: 4096 | E6: 9.36 | F6: 1.0678123e+08 | G6: 0.02 | H6: 0.02
A7: find | B7: avl | C7: random | D7: 4096 | E7: 11.76 | F7: 85038650 | G7: 0.029 | H7: 0.03
A8: find | B8: map | C8: sorted | D8: 16384 | E8: 66.79 | F8: 14972129 | G8: 0.005 | H8: 0.15
A9: find | B9: map | C9: random | D9: 16384 | E9: 59.66 | F9: 16761627 | G9: 0.005 | H9: 0.15
A10: find | B10: rb | C10: sorted | D10: 16384 | E10: 26.8 | F10: 37318743 | G10: 0.001 | H10: 0.07
A11: find | B11: rb | C11: random | D11: 16384 | E11: 24.14 | F11: 41431782 | G11: 0.001 | H11: 0.06
A12: find | B12: avl | C12: sorted | D12: 16384 | E12: 18.18 | F12: 54995278 | G12: 0.003 | H12: 0.04
A13: find | B13: avl | C13: random | D13: 16384 | E13: 21.54 | F13: 46433523 | G13: 0.006 | H13: 0.05
A14: find | B14: map | C14: sorted | D14: 65536 | E14: 102.49 | F14: 9756798.4 | G14: 0.025 | H14: 0.25
A15: find | B15: map | C15: random | D15: 65536 | E15: 95.91 | F15: 10425971 | G15: 0.006 | H15: 0.23
A16: find | B16: rb | C16: sorted | D16: 65536 | E16: 41.04 | F16: 24369302 | G16: 0.004 | H16: 0.1
... A20: find | B20: map | C20: sorted | D20: 262144 | E20: 190.56 | F20: 5247597 | G20: 0.041 | H20: 0.45
A21: find | B21: map | C21: random | D21: 262144 | E21: 180.33 | F21: 5545294.2 | G21: 0.051 | H21: 0.44 | I21: Yes
A22: find | B22: rb | C22: sorted | D22: 262144 | E22: 81.04 | F22: 12339216 | G22: 0.027 | H22: 0.2
A23: find | B23: rb | C23: random | D23: 262144 | E23: 74.07 | F23: 13499851 | G23: 0.012 | H23: 0.18
A24: find | B24: avl | C24: sorted | D24: 262144 | E24: 49.86 | F24: 20054312 | G24: 0.016 | H24: 0.12
A25: find | B25: avl | C25: random | D25: 262144 | E25: 52.38 | F25: 19089784 | G25: 0.002 | H25: 0.13
A26: insert | B26: map | C26: sorted | D26: 4096 | E26: 19.57 | F26: 51107368 | G26: 0.048 | H26: 0
A27: insert | B27: map | C27: random | D27: 4096 | E27: 55.27 | F27: 18094510 | G27: 0.025 | H27: 0
A28: insert | B28: rb | C28: sorted | D28: 4096 | E28: 22.81 | F28: 43838901 | G28: 0.014 | H28: 0
A29: insert | B29: rb | C29: random | D29: 4096 | E29: 37.58 | F29: 26607942 | G29: 0.016 | H29: 0
A30: insert | B30: avl | C30: sorted | D30: 4096 | E30: 25.02 | F30: 39960586 | G30: 0.026 | H30: 0
A31: insert | B31: avl | C31: random | D31: 4096 | E31: 60.49 | F31: 16531928 | G31: 0.024 | H31: 0
A32: insert | B32: map | C32: sorted | D32: 16384 | E32: 23.34 | F32: 42845636 | G32: 0.069 | H32: 0 | I32: Yes
A33: insert | B33: map | C33: random | D33: 16384 | E33: 71.8 | F33: 13927686 | G33: 0.017 | H33: 0.01
A34: insert | B34: rb | C34: sorted | D34: 16384 | E34: 30.42 | F34: 32874382 | G34: 0.068 | H34: 0.01 | I34: Yes
A35: insert | B35: rb | C35: random | D35: 16384 | E35: 58.02 | F35: 17234923 | G35: 0.031 | H35: 0.01
A36: insert | B36: avl | C36: sorted | D36: 16384 | E36: 30.03 | F36: 33298783 | G36: 0.03 | H36: 0.01
A37: insert | B37: avl | C37: random | D37: 16384 | E37: 78.67 | F37: 12711092 | G37: 0.004 | H37: 0.01
A38: insert | B38: map | C38: sorted | D38: 65536 | E38: 57.54 | F38: 17377783 | G38: 0.033 | H38: 0.03
A39: insert | B39: map | C39: random | D39: 65536 | E39: 94.51 | F39: 10581349 | G39: 0.013 | H39: 0.07
A40: insert | B40: rb | C40: sorted | D40: 65536 | E40: 60.9 | F40: 16419170 | G40: 0.195 | H40: 0.04 | I40: Yes
A41: insert | B41: rb | C41: random | D41: 65536 | E41: 97.33 | F41: 10274094 | G41: 0.068 | H41: 0.07 | I41: Yes
A42: insert | B42: avl | C42: sorted | D42: 65536 | E42: 33.7 | F42: 29671685 | G42: 0.075 | H42: 0.04 | I42: Yes
A43: insert | B43: avl | C43: random | D43: 65536 | E43: 119.67 | F43: 8356401.8 | G43: 0.029 | H43: 0.09
...

Sheet Run 4
A1: Operation | B1: Structure | C1: Order | D1: n | E1: ns/op | F1: ops/s | G1: Err % | H1: Total (s) | I1: Unstable
A2: find | B2: map | C2: sorted | D2: 4096 | E2: 48.23 | F2: 20734180 | G2: 0.017 | H2: 0.12
A3: find | B3: map | C3: random | D3: 4096 | E3: 40.27 | F3: 24829386 | G3: 0.007 | H3: 0.1
A4: find | B4: rb | C4: sorted | D4: 4096 | E4: 14.86 | F4: 67302624 | G4: 0.007 | H4: 0.04
A5: find | B5: rb | C5: random | D5: 4096 | E5: 13.34 | F5: 74962758 | G5: 0.02 | H5: 0.03
A6: find | B6: avl | C6: sorted | D6: 4096 | E6: 9.65 | F6: 1.0358532e+08 | G6: 0.026 | H6: 0.02
A7: find | B7: avl | C7: random | D7: 4096 | E7: 11.24 | F7: 88970359 | G7: 0.011 | H7: 0.03
A8: find | B8: map | C8: sorted | D8: 16384 | E8: 67 | F8: 14926248 | G8: 0.004 | H8: 0.15
A9: find | B9: map | C9: random | D9: 16384 | E9: 59.43 | F9: 16826553 | G9: 0.003 | H9: 0.14
A10: find | B10: rb | C10: sorted | D10: 16384 | E10: 26.59 | F10: 37604937 | G10: 0.004 | H10: 0.06
A11: find | B11: rb | C11: random | D11: 16384 | E11: 24.21 | F11: 41298189 | G11: 0.007 | H11: 0.06
A12: find | B12: avl | C12: sorted | D12: 16384 | E12: 18.3 | F12: 54653193 | G12: 0.003 | H12: 0.04
A13: find | B13: avl | C13: random | D13: 16384 | E13: 21.14 | F13: 47297100 | G13: 0.008 | H13: 0.05
... A20: find | B20: map | C20: sorted | D20: 262144 | E20: 192.69 | F20: 5189561.5 | G20: 0.034 | H20: 0.47
A21: find | B21: map | C21: random | D21: 262144 | E21: 189.85 | F21: 5267379.2 | G21: 0.05 | H21: 0.47 | I21: Yes
A22: find | B22: rb | C22: sorted | D22: 262144 | E22: 77.22 | F22: 12950052 | G22: 0.009 | H22: 0.19
A23: find | B23: rb | C23: random | D23: 262144 | E23: 78.06 | F23: 12811233 | G23: 0.027 | H23: 0.19
A24: find | B24: avl | C24: sorted | D24: 262144 | E24: 49.37 | F24: 20257245 | G24: 0.009 | H24: 0.12
A25: find | B25: avl | C25: random | D25: 262144 | E25: 53.83 | F25: 18576490 | G25: 0.012 | H25: 0.13
A26: insert | B26: map | C26: sorted | D26: 4096 | E26: 20.31 | F26: 49235503 | G26: 0.033 | H26: 0
A27: insert | B27: map | C27: random | D27: 4096 | E27: 56.52 | F27: 17693610 | G27: 0.005 | H27: 0
A28: insert | B28: rb | C28: sorted | D28: 4096 | E28: 23.25 | F28: 43011204 | G28: 0.034 | H28: 0
A29: insert | B29: rb | C29: random | D29: 4096 | E29: 38.41 | F29: 26033788 | G29: 0.017 | H29: 0
A30: insert | B30: avl | C30: sorted | D30: 4096 | E30: 25.28 | F30: 39562265 | G30: 0.066 | H30: 0 | I30: Yes
A31: insert | B31: avl | C31: random | D31: 4096 | E31: 61.75 | F31: 16195228 | G31: 0.013 | H31: 0
A32: insert | B32: map | C32: sorted | D32: 16384 | E32: 24.47 | F32: 40865804 | G32: 0.083 | H32: 0 | I32: Yes
A33: insert | B33: map | C33: random | D33: 16384 | E33: 71.37 | F33: 14011994 | G33: 0.015 | H33: 0.01
A34: insert | B34: rb | C34: sorted | D34: 16384 | E34: 29.42 | F34: 33985073 | G34: 0.031 | H34: 0.01
A35: insert | B35: rb | C35: random | D35: 16384 | E35: 58.61 | F35: 17061211 | G35: 0.022 | H35: 0.01
A36: insert | B36: avl | C36: sorted | D36: 16384 | E36: 29.71 | F36: 33662964 | G36: 0.034 | H36: 0.01
A37: insert | B37: avl | C37: random | D37: 16384 | E37: 79.36 | F37: 12601080 | G37: 0.007 | H37: 0.01
A38: insert | B38: map | C38: sorted | D38: 65536 | E38: 58.4 | F38: 17123835 | G38: 0.015 | H38: 0.03
A39: insert | B39: map | C39: random | D39: 65536 | E39: 95.4 | F39: 10482396 | G39: 0.006 | H39: 0.07
A40: insert | B40: rb | C40: sorted | D40: 65536 | E40: 58.59 | F40: 17067676 | G40: 0.223 | H40: 0.04 | I40: Yes
A41: insert | B41: rb | C41: random | D41: 65536 | E41: 105.25 | F41: 9500825.4 | G41: 0.035 | H41: 0.07
A42: insert | B42: avl | C42: sorted | D42: 65536 | E42: 32.62 | F42: 30656015 | G42: 0.016 | H42: 0.04
A43: insert | B43: avl | C43: random | D43: 65536 | E43: 124.09 | F43: 8058452.3 | G43: 0.013 | H43: 0.09
A44: insert | B44: map | C44: sorted | D44: 262144 | E44: 77.34 | F44: 12929941 | G44: 0.088 | H44: 0.22 | I44: Yes
A45: insert | B45: map | C45: random | D45: 262144 | E45: 149.98 | F45: 6667628.8 | G45: 0.023 | H45: 0.43
A46: insert | B46: rb | C46: sorted | D46: 262144 | E46: 85.28 | F46: 11725563 | G46: 0.061 | H46: 0.24 | I46: Yes
...

Sheet Run 5
A1: Operation | B1: Structure | C1: Order | D1: n | E1: ns/op | F1: ops/s | G1: Err % | H1: Total (s) | I1: Unstable
A2: find | B2: map | C2: sorted | D2: 4096 | E2: 47.6 | F2: 21006645 | G2: 0.01 | H2: 0.12
A3: find | B3: map | C3: random | D3: 4096 | E3: 41.19 | F3: 24280471 | G3: 0.008 | H3: 0.1
A4: find | B4: rb | C4: sorted | D4: 4096 | E4: 13.12 | F4: 76193429 | G4: 0.017 | H4: 0.03
A5: find | B5: rb | C5: random | D5: 4096 | E5: 12.49 | F5: 80075966 | G5: 0.008 | H5: 0.03
A6: find | B6: avl | C6: sorted | D6: 4096 | E6: 9.95 | F6: 1.0048804e+08 | G6: 0.014 | H6: 0.02
A7: find | B7: avl | C7: random | D7: 4096 | E7: 11.73 | F7: 85264274 | G7: 0.014 | H7: 0.03
A8: find | B8: map | C8: sorted | D8: 16384 | E8: 66.6 | F8: 15015170 | G8: 0.006 | H8: 0.15
A9: find | B9: map | C9: random | D9: 16384 | E9: 59.5 | F9: 16805411 | G9: 0.015 | H9: 0.14
A10: find | B10: rb | C10: sorted | D10: 16384 | E10: 26.61 | F10: 37574109 | G10: 0.008 | H10: 0.06
A11: find | B11: rb | C11: random | D11: 16384 | E11: 23.83 | F11: 41955645 | G11: 0.016 | H11: 0.06
A12: find | B12: avl | C12: sorted | D12: 16384 | E12: 17.89 | F12: 55900532 | G12: 0.006 | H12: 0.04
A13: find | B13: avl | C13: random | D13: 16384 | E13: 21.44 | F13: 46635795 | G13: 0.008 | H13: 0.05
... A25: find | B25: avl | C25: random | D25: 262144 | E25: 52.64 | F25: 18998396 | G25: 0.006 | H25: 0.13
A26: insert | B26: map | C26: sorted | D26: 4096 | E26: 19.24 | F26: 51979036 | G26: 0.05 | H26: 0 | I26: Yes
A27: insert | B27: map | C27: random | D27: 4096 | E27: 55.44 | F27: 18036028 | G27: 0.025 | H27: 0
A28: insert | B28: rb | C28: sorted | D28: 4096 | E28: 23.45 | F28: 42648452 | G28: 0.011 | H28: 0
A29: insert | B29: rb | C29: random | D29: 4096 | E29: 37.95 | F29: 26347444 | G29: 0.018 | H29: 0
A30: insert | B30: avl | C30: sorted | D30: 4096 | E30: 25.81 | F30: 38743852 | G30: 0.015 | H30: 0
A31: insert | B31: avl | C31: random | D31: 4096 | E31: 60.73 | F31: 16466464 | G31: 0.02 | H31: 0
A32: insert | B32: map | C32: sorted | D32: 16384 | E32: 24.04 | F32: 41599171 | G32: 0.071 | H32: 0 | I32: Yes
A33: insert | B33: map | C33: random | D33: 16384 | E33: 70.05 | F33: 14275893 | G33: 0.013 | H33: 0.01
A34: insert | B34: rb | C34: sorted | D34: 16384 | E34: 28.12 | F34: 35560726 | G34: 0.022 | H34: 0.01
A35: insert | B35: rb | C35: random | D35: 16384 | E35: 57.63 | F35: 17353303 | G35: 0.023 | H35: 0.01
A36: insert | B36: avl | C36: sorted | D36: 16384 | E36: 29.78 | F36: 33577624 | G36: 0.043 | H36: 0.01
A37: insert | B37: avl | C37: random | D37: 16384 | E37: 78.33 | F37: 12767085 | G37: 0.008 | H37: 0.01
A38: insert | B38: map | C38: sorted | D38: 65536 | E38: 55.85 | F38: 17906128 | G38: 0.05 | H38: 0.03
A39: insert | B39: map | C39: random | D39: 65536 | E39: 94.07 | F39: 10629989 | G39: 0.012 | H39: 0.07
A40: insert | B40: rb | C40: sorted | D40: 65536 | E40: 67.19 | F40: 14882802 | G40: 0.235 | H40: 0.05 | I40: Yes
A41: insert | B41: rb | C41: random | D41: 65536 | E41: 102 | F41: 9803522.7 | G41: 0.059 | H41: 0.07 | I41: Yes
A42: insert | B42: avl | C42: sorted | D42: 65536 | E42: 33.94 | F42: 29461135 | G42: 0.034 | H42: 0.04
A43: insert | B43: avl | C43: random | D43: 65536 | E43: 115.13 | F43: 8685873.3 | G43: 0.01 | H43: 0.08
A44: insert | B44: map | C44: sorted | D44: 262144 | E44: 75.75 | F44: 13202171 | G44: 0.078 | H44: 0.21 | I44: Yes
A45: insert | B45: map | C45: random | D45: 262144 | E45: 151.99 | F45: 6579233.5 | G45: 0.024 | H45: 0.43
A46: insert | B46: rb | C46: sorted | D46: 262144 | E46: 73.22 | F46: 13657275 | G46: 0.021 | H46: 0.2
A47: insert | B47: rb | C47: random | D47: 262144 | E47: 185.31 | F47: 5396222.4 | G47: 0.017 | H47: 0.53
A48: insert | B48: avl | C48: sorted | D48: 262144 | E48: 42.97 | F48: 23270948 | G48: 0.019 | H48: 0.22
A49: insert | B49: avl | C49: random | D49: 262144 | E49: 188.04 | F49: 5317955.2 | G49: 0.011 | H49: 0.54
A50: erase | B50: map | C50: sorted | D50: 4096 | E50: 16.66 | F50: 60009376 | G50: 0.021 | H50: 0
A51: erase | B51: map | C51: random | D51: 4096 | E51: 59.54 | F51: 16794319 | G51: 0.035 | H51: 0
...

Sheet Run 6
A1: Operation | B1: Structure | C1: Order | D1: n | E1: ns/op | F1: ops/s | G1: Err % | H1: Total (s) | I1: Unstable
A2: find | B2: map | C2: sorted | D2: 4096 | E2: 46.97 | F2: 21289153 | G2: 0.013 | H2: 0.11
A3: find | B3: map | C3: random | D3: 4096 | E3: 41.03 | F3: 24374210 | G3: 0.012 | H3: 0.1
A4: find | B4: rb | C4: sorted | D4: 4096 | E4: 13.99 | F4: 71475160 | G4: 0.008 | H4: 0.03
A5: find | B5: rb | C5: random | D5: 4096 | E5: 13.25 | F5: 75485100 | G5: 0.014 | H5: 0.03
A6: find | B6: avl | C6: sorted | D6: 4096 | E6: 9.43 | F6: 1.0609585e+08 | G6: 0.01 | H6: 0.02
A7: find | B7: avl | C7: random | D7: 4096 | E7: 11.42 | F7: 87598426 | G7: 0.012 | H7: 0.03
A8: find | B8: map | C8: sorted | D8: 16384 | E8: 66.96 | F8: 14934262 | G8: 0.005 | H8: 0.15
A9: find | B9: map | C9: random | D9: 16384 | E9: 58.67 | F9: 17043301 | G9: 0.004 | H9: 0.14
A10: find | B10: rb | C10: sorted | D10: 16384 | E10: 26.58 | F10: 37616436 | G10: 0.006 | H10: 0.06
A11: find | B11: rb | C11: random | D11: 16384 | E11: 24.1 | F11: 41494203 | G11: 0.012 | H11: 0.06
A12: find | B12: avl | C12: sorted | D12: 16384 | E12: 17.77 | F12: 56266288 | G12: 0.012 | H12: 0.04
A13: find | B13: avl | C13: random | D13: 16384 | E13: 21.41 | F13: 46711641 | G13: 0.005 | H13: 0.05
... A31: insert | B31: avl | C31: random | D31: 4096 | E31: 60.77 | F31: 16455350 | G31: 0.017 | H31: 0
A32: insert | B32: map | C32: sorted | D32: 16384 | E32: 23.64 | F32: 42306510 | G32: 0.072 | H32: 0 | I32: Yes
A33: insert | B33: map | C33: random | D33: 16384 | E33: 71.34 | F33: 14016477 | G33: 0.016 | H33: 0.01
A34: insert | B34: rb | C34: sorted | D34: 16384 | E34: 29.02 | F34: 34456579 | G34: 0.02 | H34: 0.01
A35: insert | B35: rb | C35: random | D35: 16384 | E35: 58.21 | F35: 17178110 | G35: 0.008 | H35: 0.01
A36: insert | B36: avl | C36: sorted | D36: 16384 | E36: 30.72 | F36: 32551920 | G36: 0.045 | H36: 0.01
A37: insert | B37: avl | C37: random | D37: 16384 | E37: 79.46 | F37: 12585641 | G37: 0.005 | H37: 0.01
A38: insert | B38: map | C38: sorted | D38: 65536 | E38: 59.19 | F38: 16895734 | G38: 0.025 | H38: 0.03
A39: insert | B39: map | C39: random | D39: 65536 | E39: 94.78 | F39: 10550523 | G39: 0.006 | H39: 0.07
A40: insert | B40: rb | C40: sorted | D40: 65536 | E40: 57.75 | F40: 17314819 | G40: 0.201 | H40: 0.04 | I40: Yes
A41: insert | B41: rb | C41: random | D41: 65536 | E41: 104.89 | F41: 9534148.3 | G41: 0.03 | H41: 0.07
A42: insert | B42: avl | C42: sorted | D42: 65536 | E42: 33.81 | F42: 29577838 | G42: 0.049 | H42: 0.04
A43: insert | B43: avl | C43: random | D43: 65536 | E43: 118.81 | F43: 8416577.4 | G43: 0.033 | H43: 0.08
A44: insert | B44: map | C44: sorted | D44: 262144 | E44: 75.22 | F44: 13294711 | G44: 0.096 | H44: 0.21 | I44: Yes
A45: insert | B45: map | C45: random | D45: 262144 | E45: 149.08 | F45: 6707818.8 | G45: 0.012 | H45: 0.43
A46: insert | B46: rb | C46: sorted | D46: 262144 | E46: 84.46 | F46: 11839516 | G46: 0.079 | H46: 0.24 | I46: Yes
A47: insert | B47: rb | C47: random | D47: 262144 | E47: 191.05 | F47: 5234321.4 | G47: 0.019 | H47: 0.56
A48: insert | B48: avl | C48: sorted | D48: 262144 | E48: 43.74 | F48: 22863917 | G48: 0.066 | H48: 0.22 | I48: Yes
A49: insert | B49: avl | C49: random | D49: 262144 | E49: 202.3 | F49: 4943272.9 | G49: 0.038 | H49: 0.6
A50: erase | B50: map | C50: sorted | D50: 4096 | E50: 17.12 | F50: 58403319 | G50: 0.025 | H50: 0
A51: erase | B51: map | C51: random | D51: 4096 | E51: 58.27 | F51: 17160190 | G51: 0.017 | H51: 0
A52: erase | B52: rb | C52: sorted | D52: 4096 | E52: 14.62 | F52: 68413756 | G52: 0.05 | H52: 0 | I52: Yes
A53: erase | B53: rb | C53: random | D53: 4096 | E53: 38.55 | F53: 25943097 | G53: 0.02 | H53: 0
A54: erase | B54: avl | C54: sorted | D54: 4096 | E54: 20.02 | F54: 49952438 | G54: 0.065 | H54: 0 | I54: Yes
A55: erase | B55: avl | C55: random | D55: 4096 | E55: 62.2 | F55: 16076804 | G55: 0.011 | H55: 0
A56: erase | B56: map | C56: sorted | D56: 16384 | E56: 18.85 | F56: 53050638 | G56: 0.071 | H56: 0 | I56: Yes
A57: erase | B57: map | C57: random | D57: 16384 | E57: 80.69 | F57: 12392369 | G57: 0.013 | H57: 0.01
...

Sheet Run 7
A1: Operation | B1: Structure | C1: Order | D1: n | E1: ns/op | F1: ops/s | G1: Err % | H1: Total (s) | I1: Unstable
A2: find | B2: map | C2: sorted | D2: 4096 | E2: 47.49 | F2: 21056774 | G2: 0.005 | H2: 0.12
A3: find | B3: map | C3: random | D3: 4096 | E3: 41.27 | F3: 24232521 | G3: 0.002 | H3: 0.1
A4: find | B4: rb | C4: sorted | D4: 4096 | E4: 13.03 | F4: 76769935 | G4: 0.007 | H4: 0.03
A5: find | B5: rb | C5: random | D5: 4096 | E5: 13.19 | F5: 75795069 | G5: 0.005 | H5: 0.03
A6: find | B6: avl | C6: sorted | D6: 4096 | E6: 9.78 | F6: 1.022644e+08 | G6: 0.007 | H6: 0.02
A7: find | B7: avl | C7: random | D7: 4096 | E7: 11.87 | F7: 84215481 | G7: 0.026 | H7: 0.03
A8: find | B8: map | C8: sorted | D8: 16384 | E8: 66.88 | F8: 14952346 | G8: 0.004 | H8: 0.15
A9: find | B9: map | C9: random | D9: 16384 | E9: 60.31 | F9: 16580343 | G9: 0.005 | H9: 0.15
A10: find | B10: rb | C10: sorted | D10: 16384 | E10: 27.04 | F10: 36980092 | G10: 0.002 | H10: 0.07
A11: find | B11: rb | C11: random | D11: 16384 | E11: 24.47 | F11: 40861658 | G11: 0.01 | H11: 0.06
A12: find | B12: avl | C12: sorted | D12: 16384 | E12: 18.87 | F12: 53004842 | G12: 0.017 | H12: 0.05
A13: find | B13: avl | C13: random | D13: 16384 | E13: 22.19 | F13: 45070405 | G13: 0.008 | H13: 0.05
... A28: insert | B28: rb | C28: sorted | D28: 4096 | E28: 22.47 | F28: 44511095 | G28: 0.018 | H28: 0
A29: insert | B29: rb | C29: random | D29: 4096 | E29: 38.21 | F29: 26170350 | G29: 0.054 | H29: 0 | I29: Yes
A30: insert | B30: avl | C30: sorted | D30: 4096 | E30: 25.49 | F30: 39232965 | G30: 0.017 | H30: 0
A31: insert | B31: avl | C31: random | D31: 4096 | E31: 64 | F31: 15623808 | G31: 0.021 | H31: 0
A32: insert | B32: map | C32: sorted | D32: 16384 | E32: 23.71 | F32: 42168768 | G32: 0.058 | H32: 0 | I32: Yes
A33: insert | B33: map | C33: random | D33: 16384 | E33: 73.89 | F33: 13534512 | G33: 0.011 | H33: 0.01
A34: insert | B34: rb | C34: sorted | D34: 16384 | E34: 57.8 | F34: 17300530 | G34: 0.215 | H34: 0.01 | I34: Yes
A35: insert | B35: rb | C35: random | D35: 16384 | E35: 89.04 | F35: 11231157 | G35: 0.126 | H35: 0.02 | I35: Yes
A36: insert | B36: avl | C36: sorted | D36: 16384 | E36: 30.82 | F36: 32441444 | G36: 0.031 | H36: 0.01
A37: insert | B37: avl | C37: random | D37: 16384 | E37: 85.19 | F37: 11739089 | G37: 0.034 | H37: 0.02
A38: insert | B38: map | C38: sorted | D38: 65536 | E38: 59.34 | F38: 16851368 | G38: 0.026 | H38: 0.04
A39: insert | B39: map | C39: random | D39: 65536 | E39: 96.07 | F39: 10409471 | G39: 0.016 | H39: 0.07
A40: insert | B40: rb | C40: sorted | D40: 65536 | E40: 52.71 | F40: 18971785 | G40: 0.247 | H40: 0.04 | I40: Yes
A41: insert | B41: rb | C41: random | D41: 65536 | E41: 94 | F41: 10638389 | G41: 0.041 | H41: 0.07
A42: insert | B42: avl | C42: sorted | D42: 65536 | E42: 33.54 | F42: 29816468 | G42: 0.042 | H42: 0.04
A43: insert | B43: avl | C43: random | D43: 65536 | E43: 115.11 | F43: 8687525.6 | G43: 0.031 | H43: 0.08
A44: insert | B44: map | C44: sorted | D44: 262144 | E44: 76.62 | F44: 13051290 | G44: 0.124 | H44: 0.22 | I44: Yes
A45: insert | B45: map | C45: random | D45: 262144 | E45: 148.23 | F45: 6746048.2 | G45: 0.005 | H45: 0.43
A46: insert | B46: rb | C46: sorted | D46: 262144 | E46: 83.2 | F46: 12019410 | G46: 0.013 | H46: 0.23
A47: insert | B47: rb | C47: random | D47: 262144 | E47: 194.01 | F47: 5154433.6 | G47: 0.059 | H47: 0.58 | I47: Yes
A48: insert | B48: avl | C48: sorted | D48: 262144 | E48: 44.21 | F48: 22616948 | G48: 0.052 | H48: 0.22 | I48: Yes
A49: insert | B49: avl | C49: random | D49: 262144 | E49: 187.74 | F49: 5326625.6 | G49: 0.014 | H49: 0.54
A50: erase | B50: map | C50: sorted | D50: 4096 | E50: 17.49 | F50: 57173167 | G50: 0.027 | H50: 0
A51: erase | B51: map | C51: random | D51: 4096 | E51: 58.34 | F51: 17140872 | G51: 0.021 | H51: 0
A52: erase | B52: rb | C52: sorted | D52: 4096 | E52: 14.48 | F52: 69053881 | G52: 0.041 | H52: 0
A53: erase | B53: rb | C53: random | D53: 4096 | E53: 47.17 | F53: 21198085 | G53: 0.086 | H53: 0 | I53: Yes
A54: erase | B54: avl | C54: sorted | D54: 4096 | E54: 19.93 | F54: 50186238 | G54: 0.041 | H54: 0
...

Sheet Run 8
A1: Operation | B1: Structure | C1: Order | D1: n | E1: ns/op | F1: ops/s | G1: Err % | H1: Total (s) | I1: Unstable
A2: find | B2: map | C2: sorted | D2: 4096 | E2: 46.79 | F2: 21372549 | G2: 0.013 | H2: 0.11
A3: find | B3: map | C3: random | D3: 4096 | E3: 41.12 | F3: 24320470 | G3: 0.003 | H3: 0.1
A4: find | B4: rb | C4: sorted | D4: 4096 | E4: 13.67 | F4: 73140578 | G4: 0.007 | H4: 0.03
A5: find | B5: rb | C5: random | D5: 4096 | E5: 12.59 | F5: 79401129 | G5: 0.005 | H5: 0.03
A6: find | B6: avl | C6: sorted | D6: 4096 | E6: 9.79 | F6: 1.0212957e+08 | G6: 0.003 | H6: 0.02
A7: find | B7: avl | C7: random | D7: 4096 | E7: 12.07 | F7: 82880980 | G7: 0.009 | H7: 0.03
A8: find | B8: map | C8: sorted | D8: 16384 | E8: 67.68 | F8: 14775318 | G8: 0.011 | H8: 0.15
A9: find | B9: map | C9: random | D9: 16384 | E9: 59.76 | F9: 16732572 | G9: 0.007 | H9: 0.15
A10: find | B10: rb | C10: sorted | D10: 16384 | E10: 26.9 | F10: 37170190 | G10: 0.007 | H10: 0.06
A11: find | B11: rb | C11: random | D11: 16384 | E11: 25.06 | F11: 39901400 | G11: 0.013 | H11: 0.06
A12: find | B12: avl | C12: sorted | D12: 16384 | E12: 18.15 | F12: 55095708 | G12: 0.011 | H12: 0.04
A13: find | B13: avl | C13: random | D13: 16384 | E13: 21.43 | F13: 46660914 | G13: 0.006 | H13: 0.05
... A31: insert | B31: avl | C31: random | D31: 4096 | E31: 61.55 | F31: 16245974 | G31: 0.021 | H31: 0
A32: insert | B32: map | C32: sorted | D32: 16384 | E32: 23.45 | F32: 42641348 | G32: 0.063 | H32: 0 | I32: Yes
A33: insert | B33: map | C33: random | D33: 16384 | E33: 70.67 | F33: 14150402 | G33: 0.016 | H33: 0.01
A34: insert | B34: rb | C34: sorted | D34: 16384 | E34: 29.12 | F34: 34336851 | G34: 0.019 | H34: 0.01
A35: insert | B35: rb | C35: random | D35: 16384 | E35: 57.9 | F35: 17270003 | G35: 0.012 | H35: 0.01
A36: insert | B36: avl | C36: sorted | D36: 16384 | E36: 30.43 | F36: 32863699 | G36: 0.012 | H36: 0.01
A37: insert | B37: avl | C37: random | D37: 16384 | E37: 78.75 | F37: 12698275 | G37: 0.025 | H37: 0.01
A38: insert | B38: map | C38: sorted | D38: 65536 | E38: 57.76 | F38: 17312491 | G38: 0.054 | H38: 0.03 | I38: Yes
A39: insert | B39: map | C39: random | D39: 65536 | E39: 94.34 | F39: 10599567 | G39: 0.008 | H39: 0.07
A40: insert | B40: rb | C40: sorted | D40: 65536 | E40: 70.83 | F40: 14118728 | G40: 0.215 | H40: 0.05 | I40: Yes
A41: insert | B41: rb | C41: random | D41: 65536 | E41: 104.13 | F41: 9603695.2 | G41: 0.068 | H41: 0.07 | I41: Yes
A42: insert | B42: avl | C42: sorted | D42: 65536 | E42: 33.85 | F42: 29546114 | G42: 0.046 | H42: 0.04
A43: insert | B43: avl | C43: random | D43: 65536 | E43: 119.51 | F43: 8367702.9 | G43: 0.021 | H43: 0.09
A44: insert | B44: map | C44: sorted | D44: 262144 | E44: 77.41 | F44: 12919045 | G44: 0.076 | H44: 0.22 | I44: Yes
A45: insert | B45: map | C45: random | D45: 262144 | E45: 151.17 | F45: 6615255.2 | G45: 0.026 | H45: 0.44
A46: insert | B46: rb | C46: sorted | D46: 262144 | E46: 76.82 | F46: 13016797 | G46: 0.063 | H46: 0.22 | I46: Yes
A47: insert | B47: rb | C47: random | D47: 262144 | E47: 187.8 | F47: 5324704.8 | G47: 0.034 | H47: 0.54
A48: insert | B48: avl | C48: sorted | D48: 262144 | E48: 44.45 | F48: 22498448 | G48: 0.036 | H48: 0.23
A49: insert | B49: avl | C49: random | D49: 262144 | E49: 189.16 | F49: 5286538.5 | G49: 0.025 | H49: 0.55
A50: erase | B50: map | C50: sorted | D50: 4096 | E50: 18.37 | F50: 54432617 | G50: 0.027 | H50: 0
A51: erase | B51: map | C51: random | D51: 4096 | E51: 58.25 | F51: 17168821 | G51: 0.018 | H51: 0
A52: erase | B52: rb | C52: sorted | D52: 4096 | E52: 15.15 | F52: 66003835 | G52: 0.042 | H52: 0
A53: erase | B53: rb | C53: random | D53: 4096 | E53: 38.76 | F53: 25798650 | G53: 0.038 | H53: 0
A54: erase | B54: avl | C54: sorted | D54: 4096 | E54: 20.33 | F54: 49185249 | G54: 0.061 | H54: 0 | I54: Yes
A55: erase | B55: avl | C55: random | D55: 4096 | E55: 62.84 | F55: 15913223 | G55: 0.03 | H55: 0
A56: erase | B56: map | C56: sorted | D56: 16384 | E56: 18.85 | F56: 53045486 | G56: 0.062 | H56: 0 | I56: Yes
A57: erase | B57: map | C57: random | D57: 16384 | E57: 84.23 | F57: 11872662 | G57: 0.01 | H57: 0.02
...

Sheet Run 9
A1: Operation | B1: Structure | C1: Order | D1: n | E1: ns/op | F1: ops/s | G1: Err % | H1: Total (s) | I1: Unstable
A2: find | B2: map | C2: sorted | D2: 4096 | E2: 45.89 | F2: 21789284 | G2: 0.015 | H2: 0.11
A3: find | B3: map | C3: random | D3: 4096 | E3: 41.21 | F3: 24268618 | G3: 0.005 | H3: 0.1
A4: find | B4: rb | C4: sorted | D4: 4096 | E4: 14.26 | F4: 70134378 | G4: 0.008 | H4: 0.03
A5: find | B5: rb | C5: random | D5: 4096 | E5: 12.95 | F5: 77202566 | G5: 0.016 | H5: 0.03
A6: find | B6: avl | C6: sorted | D6: 4096 | E6: 9.42 | F6: 1.0621004e+08 | G6: 0.015 | H6: 0.02
A7: find | B7: avl | C7: random | D7: 4096 | E7: 11.6 | F7: 86173435 | G7: 0.009 | H7: 0.03
A8: find | B8: map | C8: sorted | D8: 16384 | E8: 65.72 | F8: 15216736 | G8: 0.011 | H8: 0.16
A9: find | B9: map | C9: random | D9: 16384 | E9: 58.66 | F9: 17046101 | G9: 0.008 | H9: 0.14
A10: find | B10: rb | C10: sorted | D10: 16384 | E10: 26.5 | F10: 37733614 | G10: 0.014 | H10: 0.06
A11: find | B11: rb | C11: random | D11: 16384 | E11: 23.99 | F11: 41676683 | G11: 0.011 | H11: 0.06
A12: find | B12: avl | C12: sorted | D12: 16384 | E12: 18.18 | F12: 54990588 | G12: 0.013 | H12: 0.04
A13: find | B13: avl | C13: random | D13: 16384 | E13: 21.43 | F13: 46655684 | G13: 0.013 | H13: 0.05
... A29: insert | B29: rb | C29: random | D29: 4096 | E29: 37.29 | F29: 26820149 | G29: 0.017 | H29: 0
A30: insert | B30: avl | C30: sorted | D30: 4096 | E30: 24.15 | F30: 41415990 | G30: 0.051 | H30: 0 | I30: Yes
A31: insert | B31: avl | C31: random | D31: 4096 | E31: 60.92 | F31: 16414136 | G31: 0.016 | H31: 0
A32: insert | B32: map | C32: sorted | D32: 16384 | E32: 24.77 | F32: 40378449 | G32: 0.078 | H32: 0 | I32: Yes
A33: insert | B33: map | C33: random | D33: 16384 | E33: 70.35 | F33: 14214523 | G33: 0.026 | H33: 0.01
A34: insert | B34: rb | C34: sorted | D34: 16384 | E34: 27.46 | F34: 36418115 | G34: 0.025 | H34: 0
A35: insert | B35: rb | C35: random | D35: 16384 | E35: 57.48 | F35: 17396937 | G35: 0.016 | H35: 0.01
A36: insert | B36: avl | C36: sorted | D36: 16384 | E36: 29.1 | F36: 34369841 | G36: 0.068 | H36: 0.01 | I36: Yes
A37: insert | B37: avl | C37: random | D37: 16384 | E37: 78.87 | F37: 12678818 | G37: 0.006 | H37: 0.01
A38: insert | B38: map | C38: sorted | D38: 65536 | E38: 55.17 | F38: 18124210 | G38: 0.086 | H38: 0.03 | I38: Yes
A39: insert | B39: map | C39: random | D39: 65536 | E39: 93.94 | F39: 10645587 | G39: 0.005 | H39: 0.07
A40: insert | B40: rb | C40: sorted | D40: 65536 | E40: 60.8 | F40: 16446819 | G40: 0.165 | H40: 0.04 | I40: Yes
A41: insert | B41: rb | C41: random | D41: 65536 | E41: 95.66 | F41: 10453188 | G41: 0.096 | H41: 0.07 | I41: Yes
A42: insert | B42: avl | C42: sorted | D42: 65536 | E42: 32.85 | F42: 30445651 | G42: 0.044 | H42: 0.04
A43: insert | B43: avl | C43: random | D43: 65536 | E43: 115.86 | F43: 8631170.1 | G43: 0.014 | H43: 0.08
A44: insert | B44: map | C44: sorted | D44: 262144 | E44: 76.86 | F44: 13011287 | G44: 0.093 | H44: 0.22 | I44: Yes
A45: insert | B45: map | C45: random | D45: 262144 | E45: 145.41 | F45: 6877153.6 | G45: 0.005 | H45: 0.42
A46: insert | B46: rb | C46: sorted | D46: 262144 | E46: 87.77 | F46: 11393650 | G46: 0.016 | H46: 0.24
A47: insert | B47: rb | C47: random | D47: 262144 | E47: 183.5 | F47: 5449462 | G47: 0.019 | H47: 0.52
A48: insert | B48: avl | C48: sorted | D48: 262144 | E48: 44.66 | F48: 22392236 | G48: 0.033 | H48: 0.23
A49: insert | B49: avl | C49: random | D49: 262144 | E49: 190.93 | F49: 5237423.3 | G49: 0.009 | H49: 0.55
A50: erase | B50: map | C50: sorted | D50: 4096 | E50: 22.23 | F50: 44992695 | G50: 0.018 | H50: 0
A51: erase | B51: map | C51: random | D51: 4096 | E51: 64.94 | F51: 15398670 | G51: 0.017 | H51: 0
A52: erase | B52: rb | C52: sorted | D52: 4096 | E52: 14.2 | F52: 70405830 | G52: 0.068 | H52: 0 | I52: Yes
A53: erase | B53: rb | C53: random | D53: 4096 | E53: 38.21 | F53: 26167842 | G53: 0.03 | H53: 0
A54: erase | B54: avl | C54: sorted | D54: 4096 | E54: 19.03 | F54: 52551898 | G54: 0.032 | H54: 0
A55: erase | B55: avl | C55: random | D55: 4096 | E55: 62.55 | F55: 15986137 | G55: 0.011 | H55: 0
...

Sheet Run 10
A1: Operation | B1: Structure | C1: Order | D1: n | E1: ns/op | F1: ops/s | G1: Err % | H1: Total (s) | I1: Unstable
A2: find | B2: map | C2: sorted | D2: 4096 | E2: 46.4 | F2: 21551315 | G2: 0.007 | H2: 0.11
A3: find | B3: map | C3: random | D3: 4096 | E3: 41.3 | F3: 24212890 | G3: 0.005 | H3: 0.1
A4: find | B4: rb | C4: sorted | D4: 4096 | E4: 14.41 | F4: 69385866 | G4: 0.01 | H4: 0.04
A5: find | B5: rb | C5: random | D5: 4096 | E5: 12.74 | F5: 78478218 | G5: 0.005 | H5: 0.03
A6: find | B6: avl | C6: sorted | D6: 4096 | E6: 9.95 | F6: 1.0048389e+08 | G6: 0.019 | H6: 0.02
A7: find | B7: avl | C7: random | D7: 4096 | E7: 12.13 | F7: 82444425 | G7: 0.006 | H7: 0.03
A8: find | B8: map | C8: sorted | D8: 16384 | E8: 65.81 | F8: 15194458 | G8: 0.005 | H8: 0.15
A9: find | B9: map | C9: random | D9: 16384 | E9: 60.3 | F9: 16582950 | G9: 0.012 | H9: 0.15
A10: find | B10: rb | C10: sorted | D10: 16384 | E10: 26.97 | F10: 37074714 | G10: 0.001 | H10: 0.07
A11: find | B11: rb | C11: random | D11: 16384 | E11: 24.63 | F11: 40600854 | G11: 0.005 | H11: 0.06
A12: find | B12: avl | C12: sorted | D12: 16384 | E12: 18.53 | F12: 53976345 | G12: 0.004 | H12: 0.05
A13: find | B13: avl | C13: random | D13: 16384 | E13: 21.42 | F13: 46677624 | G13: 0.016 | H13: 0.05
... A31: insert | B31: avl | C31: random | D31: 4096 | E31: 59.83 | F31: 16713319 | G31: 0.014 | H31: 0
A32: insert | B32: map | C32: sorted | D32: 16384 | E32: 23.32 | F32: 42876583 | G32: 0.061 | H32: 0 | I32: Yes
A33: insert | B33: map | C33: random | D33: 16384 | E33: 69.12 | F33: 14467006 | G33: 0.006 | H33: 0.01
A34: insert | B34: rb | C34: sorted | D34: 16384 | E34: 27.96 | F34: 35767850 | G34: 0.021 | H34: 0.01
A35: insert | B35: rb | C35: random | D35: 16384 | E35: 58.45 | F35: 17109137 | G35: 0.038 | H35: 0.01
A36: insert | B36: avl | C36: sorted | D36: 16384 | E36: 27.1 | F36: 36906304 | G36: 0.039 | H36: 0
A37: insert | B37: avl | C37: random | D37: 16384 | E37: 81.69 | F37: 12240934 | G37: 0.011 | H37: 0.01
A38: insert | B38: map | C38: sorted | D38: 65536 | E38: 57.69 | F38: 17334498 | G38: 0.075 | H38: 0.03 | I38: Yes
A39: insert | B39: map | C39: random | D39: 65536 | E39: 95.5 | F39: 10471311 | G39: 0.008 | H39: 0.07
A40: insert | B40: rb | C40: sorted | D40: 65536 | E40: 55.75 | F40: 17937338 | G40: 0.219 | H40: 0.05 | I40: Yes
A41: insert | B41: rb | C41: random | D41: 65536 | E41: 116.9 | F41: 8554645.3 | G41: 0.041 | H41: 0.09
A42: insert | B42: avl | C42: sorted | D42: 65536 | E42: 32.63 | F42: 30649477 | G42: 0.06 | H42: 0.04 | I42: Yes
A43: insert | B43: avl | C43: random | D43: 65536 | E43: 119.59 | F43: 8361729.5 | G43: 0.019 | H43: 0.09
A44: insert | B44: map | C44: sorted | D44: 262144 | E44: 74.08 | F44: 13499252 | G44: 0.121 | H44: 0.21 | I44: Yes
A45: insert | B45: map | C45: random | D45: 262144 | E45: 149.7 | F45: 6680124.2 | G45: 0.019 | H45: 0.44
A46: insert | B46: rb | C46: sorted | D46: 262144 | E46: 83.27 | F46: 12009734 | G46: 0.042 | H46: 0.24
A47: insert | B47: rb | C47: random | D47: 262144 | E47: 202.29 | F47: 4943452.2 | G47: 0.089 | H47: 0.6 | I47: Yes
A48: insert | B48: avl | C48: sorted | D48: 262144 | E48: 43.7 | F48: 22880756 | G48: 0.035 | H48: 0.22
A49: insert | B49: avl | C49: random | D49: 262144 | E49: 185.63 | F49: 5386964.2 | G49: 0.013 | H49: 0.54
A50: erase | B50: map | C50: sorted | D50: 4096 | E50: 17.12 | F50: 58400821 | G50: 0.028 | H50: 0
A51: erase | B51: map | C51: random | D51: 4096 | E51: 58.95 | F51: 16964877 | G51: 0.017 | H51: 0
A52: erase | B52: rb | C52: sorted | D52: 4096 | E52: 14.48 | F52: 69045733 | G52: 0.035 | H52: 0
A53: erase | B53: rb | C53: random | D53: 4096 | E53: 39.44 | F53: 25353752 | G53: 0.054 | H53: 0 | I53: Yes
A54: erase | B54: avl | C54: sorted | D54: 4096 | E54: 18.69 | F54: 53512405 | G54: 0.072 | H54: 0 | I54: Yes
A55: erase | B55: avl | C55: random | D55: 4096 | E55: 62.72 | F55: 15942830 | G55: 0.015 | H55: 0
A56: erase | B56: map | C56: sorted | D56: 16384 | E56: 18.81 | F56: 53158216 | G56: 0.069 | H56: 0 | I56: Yes
A57: erase | B57: map | C57: random | D57: 16384 | E57: 80.64 | F57: 12401139 | G57: 0.009 | H57: 0.01
...

Sheet Run 11
A1: Operation | B1: Structure | C1: Order | D1: n | E1: ns/op | F1: ops/s | G1: Err % | H1: Total (s) | I1: Unstable
A2: find | B2: map | C2: sorted | D2: 4096 | E2: 45.93 | F2: 21773441 | G2: 0.008 | H2: 0.11
A3: find | B3: map | C3: random | D3: 4096 | E3: 41.06 | F3: 24354167 | G3: 0.004 | H3: 0.1
A4: find | B4: rb | C4: sorted | D4: 4096 | E4: 14.35 | F4: 69669078 | G4: 0.008 | H4: 0.03
A5: find | B5: rb | C5: random | D5: 4096 | E5: 12.54 | F5: 79731542 | G5: 0.018 | H5: 0.03
A6: find | B6: avl | C6: sorted | D6: 4096 | E6: 9.47 | F6: 1.0558708e+08 | G6: 0.019 | H6: 0.02
A7: find | B7: avl | C7: random | D7: 4096 | E7: 11.46 | F7: 87291916 | G7: 0.017 | H7: 0.03
A8: find | B8: map | C8: sorted | D8: 16384 | E8: 65.18 | F8: 15342962 | G8: 0.005 | H8: 0.16
A9: find | B9: map | C9: random | D9: 16384 | E9: 59.57 | F9: 16785824 | G9: 0.014 | H9: 0.14
A10: find | B10: rb | C10: sorted | D10: 16384 | E10: 26.01 | F10: 38451447 | G10: 0.005 | H10: 0.06
A11: find | B11: rb | C11: random | D11: 16384 | E11: 23.67 | F11: 42240136 | G11: 0.006 | H11: 0.06
A12: find | B12: avl | C12: sorted | D12: 16384 | E12: 18 | F12: 55570832 | G12: 0.01 | H12: 0.04
A13: find | B13: avl | C13: random | D13: 16384 | E13: 20.71 | F13: 48290348 | G13: 0.007 | H13: 0.05
... A31: insert | B31: avl | C31: random | D31: 4096 | E31: 60.26 | F31: 16595358 | G31: 0.013 | H31: 0
A32: insert | B32: map | C32: sorted | D32: 16384 | E32: 23.6 | F32: 42368871 | G32: 0.053 | H32: 0 | I32: Yes
A33: insert | B33: map | C33: random | D33: 16384 | E33: 69.18 | F33: 14455365 | G33: 0.02 | H33: 0.01
A34: insert | B34: rb | C34: sorted | D34: 16384 | E34: 29.15 | F34: 34310820 | G34: 0.048 | H34: 0.01
A35: insert | B35: rb | C35: random | D35: 16384 | E35: 56.82 | F35: 17599888 | G35: 0.012 | H35: 0.01
A36: insert | B36: avl | C36: sorted | D36: 16384 | E36: 30.5 | F36: 32791151 | G36: 0.027 | H36: 0.01
A37: insert | B37: avl | C37: random | D37: 16384 | E37: 78.42 | F37: 12751852 | G37: 0.002 | H37: 0.01
A38: insert | B38: map | C38: sorted | D38: 65536 | E38: 56.8 | F38: 17606243 | G38: 0.038 | H38: 0.03
A39: insert | B39: map | C39: random | D39: 65536 | E39: 94.19 | F39: 10616491 | G39: 0.036 | H39: 0.07
A40: insert | B40: rb | C40: sorted | D40: 65536 | E40: 53.84 | F40: 18574969 | G40: 0.29 | H40: 0.04 | I40: Yes
A41: insert | B41: rb | C41: random | D41: 65536 | E41: 99.18 | F41: 10082418 | G41: 0.062 | H41: 0.07 | I41: Yes
A42: insert | B42: avl | C42: sorted | D42: 65536 | E42: 32.63 | F42: 30644003 | G42: 0.038 | H42: 0.04
A43: insert | B43: avl | C43: random | D43: 65536 | E43: 119.54 | F43: 8365270.9 | G43: 0.019 | H43: 0.09
A44: insert | B44: map | C44: sorted | D44: 262144 | E44: 76.79 | F44: 13023114 | G44: 0.107 | H44: 0.22 | I44: Yes
A45: insert | B45: map | C45: random | D45: 262144 | E45: 148.48 | F45: 6734706.7 | G45: 0.013 | H45: 0.43
A46: insert | B46: rb | C46: sorted | D46: 262144 | E46: 82.25 | F46: 12158137 | G46: 0.01 | H46: 0.23
A47: insert | B47: rb | C47: random | D47: 262144 | E47: 190.87 | F47: 5239295.7 | G47: 0.022 | H47: 0.55
A48: insert | B48: avl | C48: sorted | D48: 262144 | E48: 44.81 | F48: 22316124 | G48: 0.02 | H48: 0.22
A49: insert | B49: avl | C49: random | D49: 262144 | E49: 209.8 | F49: 4766357.4 | G49: 0.048 | H49: 0.61
A50: erase | B50: map | C50: sorted | D50: 4096 | E50: 18.94 | F50: 52786226 | G50: 0.02 | H50: 0
A51: erase | B51: map | C51: random | D51: 4096 | E51: 58.7 | F51: 17036073 | G51: 0.017 | H51: 0
A52: erase | B52: rb | C52: sorted | D52: 4096 | E52: 15.23 | F52: 65650494 | G52: 0.088 | H52: 0 | I52: Yes
A53: erase | B53: rb | C53: random | D53: 4096 | E53: 39.07 | F53: 25594241 | G53: 0.015 | H53: 0
A54: erase | B54: avl | C54: sorted | D54: 4096 | E54: 20.14 | F54: 49658116 | G54: 0.03 | H54: 0
A55: erase | B55: avl | C55: random | D55: 4096 | E55: 62.46 | F55: 16009568 | G55: 0.009 | H55: 0
A56: erase | B56: map | C56: sorted | D56: 16384 | E56: 19 | F56: 52631072 | G56: 0.081 | H56: 0 | I56: Yes
A57: erase | B57: map | C57: random | D57: 16384 | E57: 87.18 | F57: 11470682 | G57: 0.014 | H57: 0.02
...
