Workbook

Sheet Notes
A1: Benchmark: build/tree_benchmark, compiled with g++ 13.3.0 -std=c++20 -O3 -DNDEBUG
A2: Machine: Liang Zhou's laptop, Ubuntu 24.04 (WSL), pinned with taskset -c 2
A3: Source: results_o3/run_1.txt to run_11.txt (nanobench output, parsed unchanged)
A4: Median sheet: MEDIAN of ns/op over the 11 run sheets (formulas)
A5: Ratios sheet: computed from the Median sheet at n = 262144 (2^18)
A6: Unstable = nanobench flagged the row (err% high); insert/erase rows time one pass of n keys, so they are noisier

Sheet Median
A1: Operation | B1: Structure | C1: Order | D1: n | E1: Median ns/op | F1: Min ns/op | G1: Max ns/op | H1: Unstable runs
A2: find | B2: map | C2: sorted | D2: 4096 | E2: =MEDIAN('Run 1'!E2,'Run 2'!E2,'Run 3'!E2,'Run 4'!E2,'Run 5'!E2,'Run 6'!E2,'Run 7'!E2,'Run 8'!E2,'Run 9'!E2,'Run 10'!E2,'Run 11'!E2) -> 46.78 | F2: =MIN('Run 1'!E2,'Run 2'!E2,'Run 3'!E2,'Run 4'!E2,'Run 5'!E2,'Run 6'!E2,'Run 7'!E2,'Run 8'!E2,'Run 9'!E2,'Run 10'!E2,'Run 11'!E2) -> 45.57 | G2: =MAX('Run 1'!E2,'Run 2'!E2,'Run 3'!E2,'Run 4'!E2,'Run 5'!E2,'Run 6'!E2,'Run 7'!E2,'Run 8'!E2,'Run 9'!E2,'Run 10'!E2,'Run 11'!E2) -> 53.86 | H2: =COUNTIF('Run 1'!I2,"Yes")+COUNTIF('Run 2'!I2,"Yes")+COUNTIF('Run 3'!I2,"Yes")+COUNTIF('Run 4'!I2,"Yes")+COUNTIF('Run 5'!I2,"Yes")+COUNTIF('Run 6'!I2,"Yes")+COUNTIF('Run 7'!I2,"Yes")+COUNTIF('Run 8'!I2,"Yes")+COUNTIF('Run 9'!I2,"Yes")+COUNTIF('Run 10'!I2,"Yes")+COUNTIF('Run 11'!I2,"Yes") -> 0
A3: find | B3: map | C3: random | D3: 4096 | E3: =MEDIAN('Run 1'!E3,'Run 2'!E3,'Run 3'!E3,'Run 4'!E3,'Run 5'!E3,'Run 6'!E3,'Run 7'!E3,'Run 8'!E3,'Run 9'!E3,'Run 10'!E3,'Run 11'!E3) -> 41.05 | F3: =MIN('Run 1'!E3,'Run 2'!E3,'Run 3'!E3,'Run 4'!E3,'Run 5'!E3,'Run 6'!E3,'Run 7'!E3,'Run 8'!E3,'Run 9'!E3,'Run 10'!E3,'Run 11'!E3) -> 38.27 | G3: =MAX('Run 1'!E3,'Run 2'!E3,'Run 3'!E3,'Run 4'!E3,'Run 5'!E3,'Run 6'!E3,'Run 7'!E3,'Run 8'!E3,'Run 9'!E3,'Run 10'!E3,'Run 11'!E3) -> 42.27 | H3: =COUNTIF('Run 1'!I3,"Yes")+COUNTIF('Run 2'!I3,"Yes")+COUNTIF('Run 3'!I3,"Yes")+COUNTIF('Run 4'!I3,"Yes")+COUNTIF('Run 5'!I3,"Yes")+COUNTIF('Run 6'!I3,"Yes")+COUNTIF('Run 7'!I3,"Yes")+COUNTIF('Run 8'!I3,"Yes")+COUNTIF('Run 9'!I3,"Yes")+COUNTIF('Run 10'!I3,"Yes")+COUNTIF('Run 11'!I3,"Yes") -> 0
A4: find | B4: rb | C4: sorted | D4: 4096 | E4: =MEDIAN('Run 1'!E4,'Run 2'!E4,'Run 3'!E4,'Run 4'!E4,'Run 5'!E4,'Run 6'!E4,'Run 7'!E4,'Run 8'!E4,'Run 9'!E4,'Run 10'!E4,'Run 11'!E4) -> 14.62 | F4: =MIN('Run 1'!E4,'Run 2'!E4,'Run 3'!E4,'Run 4'!E4,'Run 5'!E4,'Run 6'!E4,'Run 7'!E4,'Run 8'!E4,'Run 9'!E4,'Run 10'!E4,'Run 11'!E4) -> 12.97 | G4: =MAX('Run 1'!E4,'Run 2'!E4,'Run 3'!E4,'Run 4'!E4,'Run 5'!E4,'Run 6'!E4,'Run 7'!E4,'Run 8'!E4,'Run 9'!E4,'Run 10'!E4,'Run 11'!E4) -> 15.2 | H4: =COUNTIF('Run 1'!I4,"Yes")+COUNTIF('Run 2'!I4,"Yes")+COUNTIF('Run 3'!I4,"Yes")+COUNTIF('Run 4'!I4,"Yes")+COUNTIF('Run 5'!I4,"Yes")+COUNTIF('Run 6'!I4,"Yes")+COUNTIF('Run 7'!I4,"Yes")+COUNTIF('Run 8'!I4,"Yes")+COUNTIF('Run 9'!I4,"Yes")+COUNTIF('Run 10'!I4,"Yes")+COUNTIF('Run 11'!I4,"Yes") -> 1
A5: find | B5: rb | C5: random | D5: 4096 | E5: =MEDIAN('Run 1'!E5,'Run 2'!E5,'Run 3'!E5,'Run 4'!E5,'Run 5'!E5,'Run 6'!E5,'Run 7'!E5,'Run 8'!E5,'Run 9'!E5,'Run 10'!E5,'Run 11'!E5) -> 12.44 | F5: =MIN('Run 1'!E5,'Run 2'!E5,'Run 3'!E5,'Run 4'!E5,'Run 5'!E5,'Run 6'!E5,'Run 7'!E5,'Run 8'!E5,'Run 9'!E5,'Run 10'!E5,'Run 11'!E5) -> 11.19 | G5: =MAX('Run 1'!E5,'Run 2'!E5,'Run 3'!E5,'Run 4'!E5,'Run 5'!E5,'Run 6'!E5,'Run 7'!E5,'Run 8'!E5,'Run 9'!E5,'Run 10'!E5,'Run 11'!E5) -> 12.97 | H5: =COUNTIF('Run 1'!I5,"Yes")+COUNTIF('Run 2'!I5,"Yes")+COUNTIF('Run 3'!I5,"Yes")+COUNTIF('Run 4'!I5,"Yes")+COUNTIF('Run 5'!I5,"Yes")+COUNTIF('Run 6'!I5,"Yes")+COUNTIF('Run 7'!I5,"Yes")+COUNTIF('Run 8'!I5,"Yes")+COUNTIF('Run 9'!I5,"Yes")+COUNTIF('Run 10'!I5,"Yes")+COUNTIF('Run 11'!I5,"Yes") -> 0
A6: find | B6: avl | C6: sorted | D6: 4096 | E6: =MEDIAN('Run 1'!E6,'Run 2'!E6,'Run 3'!E6,'Run 4'!E6,'Run 5'!E6,'Run 6'!E6,'Run 7'!E6,'Run 8'!E6,'Run 9'!E6,'Run 10'!E6,'Run 11'!E6) -> 9.43 | F6: =MIN('Run 1'!E6,'Run 2'!E6,'Run 3'!E6,'Run 4'!E6,'Run 5'!E6,'Run 6'!E6,'Run 7'!E6,'Run 8'!E6,'Run 9'!E6,'Run 10'!E6,'Run 11'!E6) -> 8.93 | G6: =MAX('Run 1'!E6,'Run 2'!E6,'Run 3'!E6,'Run 4'!E6,'Run 5'!E6,'Run 6'!E6,'Run 7'!E6,'Run 8'!E6,'Run 9'!E6,'Run 10'!E6,'Run 11'!E6) -> 9.98 | H6: =COUNTIF('Run 1'!I6,"Yes")+COUNTIF('Run 2'!I6,"Yes")+COUNTIF('Run 3'!I6,"Yes")+COUNTIF('Run 4'!I6,"Yes")+COUNTIF('Run 5'!I6,"Yes")+COUNTIF('Run 6'!I6,"Yes")+COUNTIF('Run 7'!I6,"Yes")+COUNTIF('Run 8'!I6,"Yes")+COUNTIF('Run 9'!I6,"Yes")+COUNTIF('Run 10'!I6,"Yes")+COUNTIF('Run 11'!I6,"Yes") -> 0
A7: find | B7: avl | C7: random | D7: 4096 | E7: =MEDIAN('Run 1'!E7,'Run 2'!E7,'Run 3'!E7,'Run 4'!E7,'Run 5'!E7,'Run 6'!E7,'Run 7'!E7,'Run 8'!E7,'Run 9'!E7,'Run 10'!E7,'Run 11'!E7) -> 11.5 | F7: =MIN('Run 1'!E7,'Run 2'!E7,'Run 3'!E7,'Run 4'!E7,'Run 5'!E7,'Run 6'!E7,'Run 7'!E7,'Run 8'!E7,'Run 9'!E7,'Run 10'!E7,'Run 11'!E7) -> 11.19 | G7: =MAX('Run 1'!E7,'Run 2'!E7,'Run 3'!E7,'Run 4'!E7,'Run 5'!E7,'Run 6'!E7,'Run 7'!E7,'Run 8'!E7,'Run 9'!E7,'Run 10'!E7,'Run 11'!E7) -> 11.94 | H7: =COUNTIF('Run 1'!I7,"Yes")+COUNTIF('Run 2'!I7,"Yes")+COUNTIF('Run 3'!I7,"Yes")+COUNTIF('Run 4'!I7,"Yes")+COUNTIF('Run 5'!I7,"Yes")+COUNTIF('Run 6'!I7,"Yes")+COUNTIF('Run 7'!I7,"Yes")+COUNTIF('Run 8'!I7,"Yes")+COUNTIF('Run 9'!I7,"Yes")+COUNTIF('Run 10'!I7,"Yes")+COUNTIF('Run 11'!I7,"Yes") -> 0
A8: find | B8: map | C8: sorted | D8: 16384 | E8: =MEDIAN('Run 1'!E8,'Run 2'!E8,'Run 3'!E8,'Run 4'!E8,'Run 5'!E8,'Run 6'!E8,'Run 7'!E8,'Run 8'!E8,'Run 9'!E8,'Run 10'!E8,'Run 11'!E8) -> 69.02 | F8: =MIN('Run 1'!E8,'Run 2'!E8,'Run 3'!E8,'Run 4'!E8,'Run 5'!E8,'Run 6'!E8,'Run 7'!E8,'Run 8'!E8,'Run 9'!E8,'Run 10'!E8,'Run 11'!E8) -> 67.82 | G8: =MAX('Run 1'!E8,'Run 2'!E8,'Run 3'!E8,'Run 4'!E8,'Run 5'!E8,'Run 6'!E8,'Run 7'!E8,'Run 8'!E8,'Run 9'!E8,'Run 10'!E8,'Run 11'!E8) -> 70.08 | H8: =COUNTIF('Run 1'!I8,"Yes")+COUNTIF('Run 2'!I8,"Yes")+COUNTIF('Run 3'!I8,"Yes")+COUNTIF('Run 4'!I8,"Yes")+COUNTIF('Run 5'!I8,"Yes")+COUNTIF('Run 6'!I8,"Yes")+COUNTIF('Run 7'!I8,"Yes")+COUNTIF('Run 8'!I8,"Yes")+COUNTIF('Run 9'!I8,"Yes")+COUNTIF('Run 10'!I8,"Yes")+COUNTIF('Run 11'!I8,"Yes") -> 0
A9: find | B9: map | C9: random | D9: 16384 | E9: =MEDIAN('Run 1'!E9,'Run 2'!E9,'Run 3'!E9,'Run 4'!E9,'Run 5'!E9,'Run 6'!E9,'Run 7'!E9,'Run 8'!E9,'Run 9'!E9,'Run 10'!E9,'Run 11'!E9) -> 61.45 | F9: =MIN('Run 1'!E9,'Run 2'!E9,'Run 3'!E9,'Run 4'!E9,'Run 5'!E9,'Run 6'!E9,'Run 7'!E9,'Run 8'!E9,'Run 9'!E9,'Run 10'!E9,'Run 11'!E9) -> 59.99 | G9: =MAX('Run 1'!E9,'Run 2'!E9,'Run 3'!E9,'Run 4'!E9,'Run 5'!E9,'Run 6'!E9,'Run 7'!E9,'Run 8'!E9,'Run 9'!E9,'Run 10'!E9,'Run 11'!E9) -> 65.58 | H9: =COUNTIF('Run 1'!I9,"Yes")+COUNTIF('Run 2'!I9,"Yes")+COUNTIF('Run 3'!I9,"Yes")+COUNTIF('Run 4'!I9,"Yes")+COUNTIF('Run 5'!I9,"Yes")+COUNTIF('Run 6'!I9,"Yes")+COUNTIF('Run 7'!I9,"Yes")+COUNTIF('Run 8'!I9,"Yes")+COUNTIF('Run 9'!I9,"Yes")+COUNTIF('Run 10'!I9,"Yes")+COUNTIF('Run 11'!I9,"Yes") -> 0
A10: find | B10: rb | C10: sorted | D10: 16384 | E10: =MEDIAN('Run 1'!E10,'Run 2'!E10,'Run 3'!E10,'Run 4'!E10,'Run 5'!E10,'Run 6'!E10,'Run 7'!E10,'Run 8'!E10,'Run 9'!E10,'Run 10'!E10,'Run 11'!E10) -> 26.58 | F10: =MIN('Run 1'!E10,'Run 2'!E10,'Run 3'!E10,'Run 4'!E10,'Run 5'!E10,'Run 6'!E10,'Run 7'!E10,'Run 8'!E10,'Run 9'!E10,'Run 10'!E10,'Run 11'!E10) -> 26.02 | G10: =MAX('Run 1'!E10,'Run 2'!E10,'Run 3'!E10,'Run 4'!E10,'Run 5'!E10,'Run 6'!E10,'Run 7'!E10,'Run 8'!E10,'Run 9'!E10,'Run 10'!E10,'Run 11'!E10) -> 31.15 | H10: =COUNTIF('Run 1'!I10,"Yes")+COUNTIF('Run 2'!I10,"Yes")+COUNTIF('Run 3'!I10,"Yes")+COUNTIF('Run 4'!I10,"Yes")+COUNTIF('Run 5'!I10,"Yes")+COUNTIF('Run 6'!I10,"Yes")+COUNTIF('Run 7'!I10,"Yes")+COUNTIF('Run 8'!I10,"Yes")+COUNTIF('Run 9'!I10,"Yes")+COUNTIF('Run 10'!I10,"Yes")+COUNTIF('Run 11'!I10,"Yes") -> 0
A11: find | B11: rb | C11: random | D11: 16384 | E11: =MEDIAN('Run 1'!E11,'Run 2'!E11,'Run 3'!E11,'Run 4'!E11,'Run 5'!E11,'Run 6'!E11,'Run 7'!E11,'Run 8'!E11,'Run 9'!E11,'Run 10'!E11,'Run 11'!E11) -> 24.19 | F11: =MIN('Run 1'!E11,'Run 2'!E11,'Run 3'!E11,'Run 4'!E11,'Run 5'!E11,'Run 6'!E11,'Run 7'!E11,'Run 8'!E11,'Run 9'!E11,'Run 10'!E11,'Run 11'!E11) -> 23.79 | G11: =MAX('Run 1'!E11,'Run 2'!E11,'Run 3'!E11,'Run 4'!E11,'Run 5'!E11,'Run 6'!E11,'Run 7'!E11,'Run 8'!E11,'Run 9'!E11,'Run 10'!E11,'Run 11'!E11) -> 25.08 | H11: =COUNTIF('Run 1'!I11,"Yes")+COUNTIF('Run 2'!I11,"Yes")+COUNTIF('Run 3'!I11,"Yes")+COUNTIF('Run 4'!I11,"Yes")+COUNTIF('Run 5'!I11,"Yes")+COUNTIF('Run 6'!I11,"Yes")+COUNTIF('Run 7'!I11,"Yes")+COUNTIF('Run 8'!I11,"Yes")+COUNTIF('Run 9'!I11,"Yes")+COUNTIF('Run 10'!I11,"Yes")+COUNTIF('Run 11'!I11,"Yes") -> 0
A12: find | B12: avl | C12: sorted | D12: 16384 | E12: =MEDIAN('Run 1'!E12,'Run 2'!E12,'Run 3'!E12,'Run 4'!E12,'Run 5'!E12,'Run 6'!E12,'Run 7'!E12,'Run 8'!E12,'Run 9'!E12,'Run 10'!E12,'Run 11'!E12) -> 17.98 | F12: =MIN('Run 1'!E12,'Run 2'!E12,'Run 3'!E12,'Run 4'!E12,'Run 5'!E12,'Run 6'!E12,'Run 7'!E12,'Run 8'!E12,'Run 9'!E12,'Run 10'!E12,'Run 11'!E12) -> 17.46 | G12: =MAX('Run 1'!E12,'Run 2'!E12,'Run 3'!E12,'Run 4'!E12,'Run 5'!E12,'Run 6'!E12,'Run 7'!E12,'Run 8'!E12,'Run 9'!E12,'Run 10'!E12,'Run 11'!E12) -> 22.37 | H12: =COUNTIF('Run 1'!I12,"Yes")+COUNTIF('Run 2'!I12,"Yes")+COUNTIF('Run 3'!I12,"Yes")+COUNTIF('Run 4'!I12,"Yes")+COUNTIF('Run 5'!I12,"Yes")+COUNTIF('Run 6'!I12,"Yes")+COUNTIF('Run 7'!I12,"Yes")+COUNTIF('Run 8'!I12,"Yes")+COUNTIF('Run 9'!I12,"Yes")+COUNTIF('Run 10'!I12,"Yes")+COUNTIF('Run 11'!I12,"Yes") -> 0
A13: find | B13: avl | C13: random | D13: 16384 | E13: =MEDIAN('Run 1'!E13,'Run 2'!E13,'Run 3'!E13,'Run 4'!E13,'Run 5'!E13,'Run 6'!E13,'Run 7'!E13,'Run 8'!E13,'Run 9'!E13,'Run 10'!E13,'Run 11'!E13) -> 21.22 | F13: =MIN('Run 1'!E13,'Run 2'!E13,'Run 3'!E13,'Run 4'!E13,'Run 5'!E13,'Run 6'!E13,'Run 7'!E13,'Run 8'!E13,'Run 9'!E13,'Run 10'!E13,'Run 11'!E13) -> 20.91 | G13: =MAX('Run 1'!E13,'Run 2'!E13,'Run 3'!E13,'Run 4'!E13,'Run 5'!E13,'Run 6'!E13,'Run 7'!E13,'Run 8'!E13,'Run 9'!E13,'Run 10'!E13,'Run 11'!E13) -> 21.83 | H13: =COUNTIF('Run 1'!I13,"Yes")+COUNTIF('Run 2'!I13,"Yes")+COUNTIF('Run 3'!I13,"Yes")+COUNTIF('Run 4'!I13,"Yes")+COUNTIF('Run 5'!I13,"Yes")+COUNTIF('Run 6'!I13,"Yes")+COUNTIF('Run 7'!I13,"Yes")+COUNTIF('Run 8'!I13,"Yes")+COUNTIF('Run 9'!I13,"Yes")+COUNTIF('Run 10'!I13,"Yes")+COUNTIF('Run 11'!I13,"Yes") -> 0
... A73: erase | B73: avl | C73: random | D73: 262144 | E73: =MEDIAN('Run 1'!E73,'Run 2'!E73,'Run 3'!E73,'Run 4'!E73,'Run 5'!E73,'Run 6'!E73,'Run 7'!E73,'Run 8'!E73,'Run 9'!E73,'Run 10'!E73,'Run 11'!E73) -> 207.9 | F73: =MIN('Run 1'!E73,'Run 2'!E73,'Run 3'!E73,'Run 4'!E73,'Run 5'!E73,'Run 6'!E73,'Run 7'!E73,'Run 8'!E73,'Run 9'!E73,'Run 10'!E73,'Run 11'!E73) -> 202.56 | G73: =MAX('Run 1'!E73,'Run 2'!E73,'Run 3'!E73,'Run 4'!E73,'Run 5'!E73,'Run 6'!E73,'Run 7'!E73,'Run 8'!E73,'Run 9'!E73,'Run 10'!E73,'Run 11'!E73) -> 217.68 | H73: =COUNTIF('Run 1'!I73,"Yes")+COUNTIF('Run 2'!I73,"Yes")+COUNTIF('Run 3'!I73,"Yes")+COUNTIF('Run 4'!I73,"Yes")+COUNTIF('Run 5'!I73,"Yes")+COUNTIF('Run 6'!I73,"Yes")+COUNTIF('Run 7'!I73,"Yes")+COUNTIF('Run 8'!I73,"Yes")+COUNTIF('Run 9'!I73,"Yes")+COUNTIF('Run 10'!I73,"Yes")+COUNTIF('Run 11'!I73,"Yes") -> 0

Sheet Ratios
A1: AVL/RB time ratio at n = 262144 (above 1 = AVL slower)
A2: Random insertion | B2: =Median!E49/Median!E47 -> 0.93638876
A3: Random deletion | B3: =Median!E73/Median!E71 -> 1.1676495
A4: Sorted insertion | B4: =Median!E48/Median!E46 -> 0.53320896
A5: Sorted deletion | B5: =Median!E72/Median!E70 -> 0.83566879
A6: Random find | B6: =Median!E25/Median!E23 -> 0.72708246
A7: Sorted find | B7: =Median!E24/Median!E22 -> 0.60806593
A9: Sorted-to-random speed ratio at n = 262144 (random time / sorted time; compare Brown Table 4)
A10: AVL insertion | B10: =Median!E49/Median!E48 -> 4.1891766
A11: AVL deletion | B11: =Median!E73/Median!E72 -> 6.3384146
A12: RB insertion | B12: =Median!E47/Median!E46 -> 2.3854478
A13: RB deletion | B13: =Median!E71/Median!E70 -> 4.5363057

Sheet Run 1
A1: Operation | B1: Structure | C1: Order | D1: n | E1: ns/op | F1: ops/s | G1: Err % | H1: Total (s) | I1: Unstable
A2: find | B2: map | C2: sorted | D2: 4096 | E2: 46.68 | F2: 21422960 | G2: 0.008 | H2: 0.11
A3: find | B3: map | C3: random | D3: 4096 | E3: 42.07 | F3: 23768061 | G3: 0.004 | H3: 0.1
A4: find | B4: rb | C4: sorted | D4: 4096 | E4: 14.69 | F4: 68089326 | G4: 0.013 | H4: 0.04
A5: find | B5: rb | C5: random | D5: 4096 | E5: 12.73 | F5: 78545771 | G5: 0.007 | H5: 0.03
A6: find | B6: avl | C6: sorted | D6: 4096 | E6: 9.68 | F6: 1.0329049e+08 | G6: 0.003 | H6: 0.02
A7: find | B7: avl | C7: random | D7: 4096 | E7: 11.19 | F7: 89352794 | G7: 0.006 | H7: 0.03
A8: find | B8: map | C8: sorted | D8: 16384 | E8: 68.75 | F8: 14545914 | G8: 0.003 | H8: 0.15
A9: find | B9: map | C9: random | D9: 16384 | E9: 61.97 | F9: 16138134 | G9: 0.009 | H9: 0.15
A10: find | B10: rb | C10: sorted | D10: 16384 | E10: 26.4 | F10: 37885235 | G10: 0.003 | H10: 0.06
A11: find | B11: rb | C11: random | D11: 16384 | E11: 24.25 | F11: 41238874 | G11: 0.008 | H11: 0.06
A12: find | B12: avl | C12: sorted | D12: 16384 | E12: 18.07 | F12: 55352421 | G12: 0.005 | H12: 0.04
A13: find | B13: avl | C13: random | D13: 16384 | E13: 21.52 | F13: 46472024 | G13: 0.008 | H13: 0.05
... A20: find | B20: map | C20: sorted | D20: 262144 | E20: 191.97 | F20: 5209230.2 | G20: 0.022 | H20: 0.46
A21: find | B21: map | C21: random | D21: 262144 | E21: 211.06 | F21: 4738081 | G21: 0.078 | H21: 0.51 | I21: Yes
A22: find | B22: rb | C22: sorted | D22: 262144 | E22: 80.48 | F22: 12424756 | G22: 0.018 | H22: 0.2
A23: find | B23: rb | C23: random | D23: 262144 | E23: 73.57 | F23: 13592884 | G23: 0.033 | H23: 0.18
A24: find | B24: avl | C24: sorted | D24: 262144 | E24: 47.58 | F24: 21018184 | G24: 0.016 | H24: 0.12
A25: find | B25: avl | C25: random | D25: 262144 | E25: 52.11 | F25: 19190578 | G25: 0.007 | H25: 0.13
A26: insert | B26: map | C26: sorted | D26: 4096 | E26: 20 | F26: 50007936 | G26: 0.022 | H26: 0
A27: insert | B27: map | C27: random | D27: 4096 | E27: 58.09 | F27: 17214279 | G27: 0.023 | H27: 0
A28: insert | B28: rb | C28: sorted | D28: 4096 | E28: 23.02 | F28: 43443214 | G28: 0.036 | H28: 0
A29: insert | B29: rb | C29: random | D29: 4096 | E29: 38.64 | F29: 25881134 | G29: 0.038 | H29: 0
A30: insert | B30: avl | C30: sorted | D30: 4096 | E30: 23.23 | F30: 43042391 | G30: 0.036 | H30: 0
A31: insert | B31: avl | C31: random | D31: 4096 | E31: 59.75 | F31: 16735171 | G31: 0.02 | H31: 0
A32: insert | B32: map | C32: sorted | D32: 16384 | E32: 24.38 | F32: 41009314 | G32: 0.072 | H32: 0 | I32: Yes
A33: insert | B33: map | C33: random | D33: 16384 | E33: 75.07 | F33: 13320065 | G33: 0.031 | H33: 0.01
A34: insert | B34: rb | C34: sorted | D34: 16384 | E34: 33.07 | F34: 30238601 | G34: 0.139 | H34: 0.01 | I34: Yes
A35: insert | B35: rb | C35: random | D35: 16384 | E35: 58.87 | F35: 16987762 | G35: 0.009 | H35: 0.01
A36: insert | B36: avl | C36: sorted | D36: 16384 | E36: 25.82 | F36: 38722882 | G36: 0.022 | H36: 0
A37: insert | B37: avl | C37: random | D37: 16384 | E37: 81.8 | F37: 12224567 | G37: 0.019 | H37: 0.01
A38: insert | B38: map | C38: sorted | D38: 65536 | E38: 58.76 | F38: 17017281 | G38: 0.027 | H38: 0.03
A39: insert | B39: map | C39: random | D39: 65536 | E39: 97.22 | F39: 10286311 | G39: 0.009 | H39: 0.08
A40: insert | B40: rb | C40: sorted | D40: 65536 | E40: 81.92 | F40: 12206968 | G40: 0.137 | H40: 0.05 | I40: Yes
A41: insert | B41: rb | C41: random | D41: 65536 | E41: 113.92 | F41: 8778027.7 | G41: 0.073 | H41: 0.09 | I41: Yes
A42: insert | B42: avl | C42: sorted | D42: 65536 | E42: 31.48 | F42: 31770317 | G42: 0.045 | H42: 0.04
A43: insert | B43: avl | C43: random | D43: 65536 | E43: 133.82 | F43: 7472457.5 | G43: 0.115 | H43: 0.1 | I43: Yes
A44: insert | B44: map | C44: sorted | D44: 262144 | E44: 79.88 | F44: 12519353 | G44: 0.118 | H44: 0.22 | I44: Yes
A45: insert | B45: map | C45: random | D45: 262144 | E45: 150.37 | F45: 6650188.3 | G45: 0.026 | H45: 0.44
A46: insert | B46: rb | C46: sorted | D46: 262144 | E46: 100.62 | F46: 9938333.9 | G46: 0.038 | H46: 0.28
...

Sheet Run 2
A1: Operation | B1: Structure | C1: Order | D1: n | E1: ns/op | F1: ops/s | G1: Err % | H1: Total (s) | I1: Unstable
A2: find | B2: map | C2: sorted | D2: 4096 | E2: 53.86 | F2: 18565478 | G2: 0.015 | H2: 0.13
A3: find | B3: map | C3: random | D3: 4096 | E3: 40.67 | F3: 24587896 | G3: 0.04 | H3: 0.1
A4: find | B4: rb | C4: sorted | D4: 4096 | E4: 14.57 | F4: 68656796 | G4: 0.015 | H4: 0.04
A5: find | B5: rb | C5: random | D5: 4096 | E5: 11.19 | F5: 89389699 | G5: 0.005 | H5: 0.03
A6: find | B6: avl | C6: sorted | D6: 4096 | E6: 8.93 | F6: 1.1196347e+08 | G6: 0.008 | H6: 0.02
A7: find | B7: avl | C7: random | D7: 4096 | E7: 11.44 | F7: 87389638 | G7: 0.019 | H7: 0.03
A8: find | B8: map | C8: sorted | D8: 16384 | E8: 70.08 | F8: 14268997 | G8: 0.006 | H8: 0.16
A9: find | B9: map | C9: random | D9: 16384 | E9: 65.58 | F9: 15248246 | G9: 0.049 | H9: 0.16
A10: find | B10: rb | C10: sorted | D10: 16384 | E10: 31.15 | F10: 32097821 | G10: 0.007 | H10: 0.08
A11: find | B11: rb | C11: random | D11: 16384 | E11: 24.68 | F11: 40514027 | G11: 0.016 | H11: 0.06
A12: find | B12: avl | C12: sorted | D12: 16384 | E12: 22.37 | F12: 44694493 | G12: 0.023 | H12: 0.05
A13: find | B13: avl | C13: random | D13: 16384 | E13: 21.83 | F13: 45800903 | G13: 0.022 | H13: 0.05
... A19: find | B19: avl | C19: random | D19: 65536 | E19: 30.32 | F19: 32978635 | G19: 0.009 | H19: 0.07
A20: find | B20: map | C20: sorted | D20: 262144 | E20: 222.35 | F20: 4497474 | G20: 0.063 | H20: 0.57 | I20: Yes
A21: find | B21: map | C21: random | D21: 262144 | E21: 212.4 | F21: 4708103.4 | G21: 0.043 | H21: 0.53
A22: find | B22: rb | C22: sorted | D22: 262144 | E22: 81.46 | F22: 12275319 | G22: 0.035 | H22: 0.2
A23: find | B23: rb | C23: random | D23: 262144 | E23: 77.86 | F23: 12844206 | G23: 0.04 | H23: 0.19
A24: find | B24: avl | C24: sorted | D24: 262144 | E24: 53.08 | F24: 18838171 | G24: 0.021 | H24: 0.13
A25: find | B25: avl | C25: random | D25: 262144 | E25: 59.01 | F25: 16945927 | G25: 0.101 | H25: 0.15 | I25: Yes
A26: insert | B26: map | C26: sorted | D26: 4096 | E26: 19.78 | F26: 50554794 | G26: 0.042 | H26: 0
A27: insert | B27: map | C27: random | D27: 4096 | E27: 54.67 | F27: 18290450 | G27: 0.014 | H27: 0
A28: insert | B28: rb | C28: sorted | D28: 4096 | E28: 21.24 | F28: 47086955 | G28: 0.026 | H28: 0
A29: insert | B29: rb | C29: random | D29: 4096 | E29: 35.56 | F29: 28122983 | G29: 0.02 | H29: 0
A30: insert | B30: avl | C30: sorted | D30: 4096 | E30: 23.42 | F30: 42703142 | G30: 0.011 | H30: 0
A31: insert | B31: avl | C31: random | D31: 4096 | E31: 59.38 | F31: 16840928 | G31: 0.012 | H31: 0
A32: insert | B32: map | C32: sorted | D32: 16384 | E32: 24.42 | F32: 40949251 | G32: 0.073 | H32: 0 | I32: Yes
A33: insert | B33: map | C33: random | D33: 16384 | E33: 71.66 | F33: 13955600 | G33: 0.02 | H33: 0.01
A34: insert | B34: rb | C34: sorted | D34: 16384 | E34: 30.94 | F34: 32317430 | G34: 0.095 | H34: 0.01 | I34: Yes
A35: insert | B35: rb | C35: random | D35: 16384 | E35: 59.85 | F35: 16709399 | G35: 0.068 | H35: 0.01 | I35: Yes
A36: insert | B36: avl | C36: sorted | D36: 16384 | E36: 25.72 | F36: 38877618 | G36: 0.056 | H36: 0 | I36: Yes
A37: insert | B37: avl | C37: random | D37: 16384 | E37: 80.8 | F37: 12376024 | G37: 0.012 | H37: 0.01
A38: insert | B38: map | C38: sorted | D38: 65536 | E38: 56.06 | F38: 17838653 | G38: 0.011 | H38: 0.03
A39: insert | B39: map | C39: random | D39: 65536 | E39: 93.07 | F39: 10744625 | G39: 0.006 | H39: 0.07
A40: insert | B40: rb | C40: sorted | D40: 65536 | E40: 54.82 | F40: 18242952 | G40: 0.337 | H40: 0.04 | I40: Yes
A41: insert | B41: rb | C41: random | D41: 65536 | E41: 94.29 | F41: 10605265 | G41: 0.111 | H41: 0.07 | I41: Yes
A42: insert | B42: avl | C42: sorted | D42: 65536 | E42: 30.45 | F42: 32835691 | G42: 0.018 | H42: 0.04
A43: insert | B43: avl | C43: random | D43: 65536 | E43: 103.82 | F43: 9632142.6 | G43: 0.031 | H43: 0.08
A44: insert | B44: map | C44: sorted | D44: 262144 | E44: 75.44 | F44: 13255763 | G44: 0.133 | H44: 0.21 | I44: Yes
A45: insert | B45: map | C45: random | D45: 262144 | E45: 146.82 | F45: 6810995.2 | G45: 0.019 | H45: 0.42
...

Sheet Run 3
A1: Operation | B1: Structure | C1: Order | D1: n | E1: ns/op | F1: ops/s | G1: Err % | H1: Total (s) | I1: Unstable
A2: find | B2: map | C2: sorted | D2: 4096 | E2: 48.88 | F2: 20457731 | G2: 0.03 | H2: 0.12
A3: find | B3: map | C3: random | D3: 4096 | E3: 39.1 | F3: 25572269 | G3: 0.014 | H3: 0.1
A4: find | B4: rb | C4: sorted | D4: 4096 | E4: 14.16 | F4: 70634362 | G4: 0.055 | H4: 0.04 | I4: Yes
A5: find | B5: rb | C5: random | D5: 4096 | E5: 12.97 | F5: 77107490 | G5: 0.003 | H5: 0.03
A6: find | B6: avl | C6: sorted | D6: 4096 | E6: 9.98 | F6: 1.0017132e+08 | G6: 0.035 | H6: 0.02
A7: find | B7: avl | C7: random | D7: 4096 | E7: 11.58 | F7: 86383664 | G7: 0.007 | H7: 0.03
A8: find | B8: map | C8: sorted | D8: 16384 | E8: 69.93 | F8: 14300307 | G8: 0.006 | H8: 0.15
A9: find | B9: map | C9: random | D9: 16384 | E9: 63.23 | F9: 15816126 | G9: 0.018 | H9: 0.15
A10: find | B10: rb | C10: sorted | D10: 16384 | E10: 26.81 | F10: 37305582 | G10: 0.005 | H10: 0.07
A11: find | B11: rb | C11: random | D11: 16384 | E11: 25.08 | F11: 39878850 | G11: 0.024 | H11: 0.06
A12: find | B12: avl | C12: sorted | D12: 16384 | E12: 17.7 | F12: 56495128 | G12: 0.006 | H12: 0.04
A13: find | B13: avl | C13: random | D13: 16384 | E13: 21.28 | F13: 46985699 | G13: 0.006 | H13: 0.05
A14: find | B14: map | C14: sorted | D14: 65536 | E14: 106.37 | F14: 9401223.1 | G14: 0.01 | H14: 0.26
A15: find | B15: map | C15: random | D15: 65536 | E15: 99.87 | F15: 10013303 | G15: 0.014 | H15: 0.24
A16: find | B16: rb | C16: sorted | D16: 65536 | E16: 41.5 | F16: 24095635 | G16: 0.003 | H16: 0.1
... A19: find | B19: avl | C19: random | D19: 65536 | E19: 30.21 | F19: 33100621 | G19: 0.004 | H19: 0.07
A20: find | B20: map | C20: sorted | D20: 262144 | E20: 209.23 | F20: 4779410.4 | G20: 0.072 | H20: 0.5 | I20: Yes
A21: find | B21: map | C21: random | D21: 262144 | E21: 241.52 | F21: 4140518.2 | G21: 0.099 | H21: 0.61 | I21: Yes
A22: find | B22: rb | C22: sorted | D22: 262144 | E22: 82.31 | F22: 12149867 | G22: 0.02 | H22: 0.2
A23: find | B23: rb | C23: random | D23: 262144 | E23: 71.1 | F23: 14064637 | G23: 0.006 | H23: 0.16
A24: find | B24: avl | C24: sorted | D24: 262144 | E24: 49.87 | F24: 20050402 | G24: 0.014 | H24: 0.12
A25: find | B25: avl | C25: random | D25: 262144 | E25: 52.11 | F25: 19191176 | G25: 0.004 | H25: 0.13
A26: insert | B26: map | C26: sorted | D26: 4096 | E26: 19.85 | F26: 50372010 | G26: 0.049 | H26: 0
A27: insert | B27: map | C27: random | D27: 4096 | E27: 56.45 | F27: 17714424 | G27: 0.023 | H27: 0
A28: insert | B28: rb | C28: sorted | D28: 4096 | E28: 21.97 | F28: 45509088 | G28: 0.017 | H28: 0
A29: insert | B29: rb | C29: random | D29: 4096 | E29: 36.45 | F29: 27437452 | G29: 0.018 | H29: 0
A30: insert | B30: avl | C30: sorted | D30: 4096 | E30: 24.17 | F30: 41368305 | G30: 0.018 | H30: 0
A31: insert | B31: avl | C31: random | D31: 4096 | E31: 59.21 | F31: 16888075 | G31: 0.022 | H31: 0
A32: insert | B32: map | C32: sorted | D32: 16384 | E32: 25.27 | F32: 39578608 | G32: 0.073 | H32: 0 | I32: Yes
A33: insert | B33: map | C33: random | D33: 16384 | E33: 72.07 | F33: 13875115 | G33: 0.016 | H33: 0.01
A34: insert | B34: rb | C34: sorted | D34: 16384 | E34: 28.26 | F34: 35383247 | G34: 0.024 | H34: 0.01
A35: insert | B35: rb | C35: random | D35: 16384 | E35: 57.74 | F35: 17319257 | G35: 0.009 | H35: 0.01
A36: insert | B36: avl | C36: sorted | D36: 16384 | E36: 27.11 | F36: 36886279 | G36: 0.027 | H36: 0
A37: insert | B37: avl | C37: random | D37: 16384 | E37: 78.08 | F37: 12807124 | G37: 0.008 | H37: 0.01
A38: insert | B38: map | C38: sorted | D38: 65536 | E38: 57.7 | F38: 17330923 | G38: 0.099 | H38: 0.04 | I38: Yes
A39: insert | B39: map | C39: random | D39: 65536 | E39: 96.21 | F39: 10393644 | G39: 0.014 | H39: 0.07
A40: insert | B40: rb | C40: sorted | D40: 65536 | E40: 58.86 | F40: 16990735 | G40: 0.263 | H40: 0.04 | I40: Yes
A41: insert | B41: rb | C41: random | D41: 65536 | E41: 100.23 | F41: 9977297.8 | G41: 0.098 | H41: 0.07 | I41: Yes
A42: insert | B42: avl | C42: sorted | D42: 65536 | E42: 31.04 | F42: 32219163 | G42: 0.021 | H42: 0.04
...

Sheet Run 4
A1: Operation | B1: Structure | C1: Order | D1: n | E1: ns/op | F1: ops/s | G1: Err % | H1: Total (s) | I1: Unstable
A2: find | B2: map | C2: sorted | D2: 4096 | E2: 47 | F2: 21278024 | G2: 0.012 | H2: 0.12
A3: find | B3: map | C3: random | D3: 4096 | E3: 42.27 | F3: 23659865 | G3: 0.014 | H3: 0.1
A4: find | B4: rb | C4: sorted | D4: 4096 | E4: 13.09 | F4: 76421143 | G4: 0.011 | H4: 0.03
A5: find | B5: rb | C5: random | D5: 4096 | E5: 12.61 | F5: 79273376 | G5: 0.026 | H5: 0.03
A6: find | B6: avl | C6: sorted | D6: 4096 | E6: 9.29 | F6: 1.0759357e+08 | G6: 0.009 | H6: 0.02
A7: find | B7: avl | C7: random | D7: 4096 | E7: 11.39 | F7: 87791551 | G7: 0.015 | H7: 0.03
A8: find | B8: map | C8: sorted | D8: 16384 | E8: 69.02 | F8: 14489138 | G8: 0.003 | H8: 0.15
A9: find | B9: map | C9: random | D9: 16384 | E9: 61.44 | F9: 16275449 | G9: 0.002 | H9: 0.15
A10: find | B10: rb | C10: sorted | D10: 16384 | E10: 26.59 | F10: 37607654 | G10: 0.006 | H10: 0.07
A11: find | B11: rb | C11: random | D11: 16384 | E11: 24.29 | F11: 41171881 | G11: 0.01 | H11: 0.06
A12: find | B12: avl | C12: sorted | D12: 16384 | E12: 18.1 | F12: 55253933 | G12: 0.003 | H12: 0.04
A13: find | B13: avl | C13: random | D13: 16384 | E13: 21.37 | F13: 46794857 | G13: 0.005 | H13: 0.05
... A25: find | B25: avl | C25: random | D25: 262144 | E25: 50.58 | F25: 19771613 | G25: 0.006 | H25: 0.12
A26: insert | B26: map | C26: sorted | D26: 4096 | E26: 20.8 | F26: 48086970 | G26: 0.059 | H26: 0 | I26: Yes
A27: insert | B27: map | C27: random | D27: 4096 | E27: 57.41 | F27: 17418817 | G27: 0.021 | H27: 0
A28: insert | B28: rb | C28: sorted | D28: 4096 | E28: 21.8 | F28: 45864266 | G28: 0.012 | H28: 0
A29: insert | B29: rb | C29: random | D29: 4096 | E29: 37.15 | F29: 26919386 | G29: 0.011 | H29: 0
A30: insert | B30: avl | C30: sorted | D30: 4096 | E30: 24.79 | F30: 40339975 | G30: 0.008 | H30: 0
A31: insert | B31: avl | C31: random | D31: 4096 | E31: 59.89 | F31: 16695947 | G31: 0.022 | H31: 0
A32: insert | B32: map | C32: sorted | D32: 16384 | E32: 23.59 | F32: 42391782 | G32: 0.055 | H32: 0 | I32: Yes
A33: insert | B33: map | C33: random | D33: 16384 | E33: 72.02 | F33: 13884499 | G33: 0.011 | H33: 0.01
A34: insert | B34: rb | C34: sorted | D34: 16384 | E34: 28.76 | F34: 34770650 | G34: 0.046 | H34: 0.01
A35: insert | B35: rb | C35: random | D35: 16384 | E35: 57.78 | F35: 17307749 | G35: 0.005 | H35: 0.01
A36: insert | B36: avl | C36: sorted | D36: 16384 | E36: 25.52 | F36: 39191297 | G36: 0.024 | H36: 0
A37: insert | B37: avl | C37: random | D37: 16384 | E37: 77.77 | F37: 12858799 | G37: 0.011 | H37: 0.01
A38: insert | B38: map | C38: sorted | D38: 65536 | E38: 58.46 | F38: 17104997 | G38: 0.032 | H38: 0.03
A39: insert | B39: map | C39: random | D39: 65536 | E39: 96.55 | F39: 10357648 | G39: 0.015 | H39: 0.07
A40: insert | B40: rb | C40: sorted | D40: 65536 | E40: 81.1 | F40: 12330024 | G40: 0.029 | H40: 0.05
A41: insert | B41: rb | C41: random | D41: 65536 | E41: 107.13 | F41: 9334754.9 | G41: 0.032 | H41: 0.08
A42: insert | B42: avl | C42: sorted | D42: 65536 | E42: 30.7 | F42: 32573050 | G42: 0.021 | H42: 0.04
A43: insert | B43: avl | C43: random | D43: 65536 | E43: 111.58 | F43: 8962387.8 | G43: 0.045 | H43: 0.08
A44: insert | B44: map | C44: sorted | D44: 262144 | E44: 76.25 | F44: 13115604 | G44: 0.161 | H44: 0.22 | I44: Yes
A45: insert | B45: map | C45: random | D45: 262144 | E45: 153.23 | F45: 6526109.7 | G45: 0.01 | H45: 0.44
A46: insert | B46: rb | C46: sorted | D46: 262144 | E46: 89.29 | F46: 11200061 | G46: 0.024 | H46: 0.25
A47: insert | B47: rb | C47: random | D47: 262144 | E47: 191.6 | F47: 5219258.3 | G47: 0.024 | H47: 0.57
A48: insert | B48: avl | C48: sorted | D48: 262144 | E48: 44.25 | F48: 22596416 | G48: 0.017 | H48: 0.22
A49: insert | B49: avl | C49: random | D49: 262144 | E49: 194.47 | F49: 5142111.8 | G49: 0.055 | H49: 0.58 | I49: Yes
A50: erase | B50: map | C50: sorted | D50: 4096 | E50: 17.56 | F50: 56938710 | G50: 0.017 | H50: 0
A51: erase | B51: map | C51: random | D51: 4096 | E51: 58.97 | F51: 16957082 | G51: 0.013 | H51: 0
...

Sheet Run 5
A1: Operation | B1: Structure | C1: Order | D1: n | E1: ns/op | F1: ops/s | G1: Err % | H1: Total (s) | I1: Unstable
A2: find | B2: map | C2: sorted | D2: 4096 | E2: 45.57 | F2: 21944428 | G2: 0.013 | H2: 0.11
A3: find | B3: map | C3: random | D3: 4096 | E3: 38.27 | F3: 26129064 | G3: 0.023 | H3: 0.09
A4: find | B4: rb | C4: sorted | D4: 4096 | E4: 12.97 | F4: 77090469 | G4: 0.008 | H4: 0.03
A5: find | B5: rb | C5: random | D5: 4096 | E5: 12.35 | F5: 80956094 | G5: 0.005 | H5: 0.03
A6: find | B6: avl | C6: sorted | D6: 4096 | E6: 9.32 | F6: 1.0734048e+08 | G6: 0.008 | H6: 0.02
A7: find | B7: avl | C7: random | D7: 4096 | E7: 11.46 | F7: 87276116 | G7: 0.012 | H7: 0.03
A8: find | B8: map | C8: sorted | D8: 16384 | E8: 67.82 | F8: 14744222 | G8: 0.007 | H8: 0.15
A9: find | B9: map | C9: random | D9: 16384 | E9: 60.21 | F9: 16608418 | G9: 0.007 | H9: 0.15
A10: find | B10: rb | C10: sorted | D10: 16384 | E10: 26.02 | F10: 38432894 | G10: 0.008 | H10: 0.06
A11: find | B11: rb | C11: random | D11: 16384 | E11: 23.79 | F11: 42040067 | G11: 0.002 | H11: 0.06
A12: find | B12: avl | C12: sorted | D12: 16384 | E12: 17.66 | F12: 56615206 | G12: 0.004 | H12: 0.04
A13: find | B13: avl | C13: random | D13: 16384 | E13: 20.95 | F13: 47743108 | G13: 0.006 | H13: 0.05
... A21: find | B21: map | C21: random | D21: 262144 | E21: 179.93 | F21: 5557847.3 | G21: 0.016 | H21: 0.44
A22: find | B22: rb | C22: sorted | D22: 262144 | E22: 82.21 | F22: 12164639 | G22: 0.06 | H22: 0.2 | I22: Yes
A23: find | B23: rb | C23: random | D23: 262144 | E23: 71.46 | F23: 13993976 | G23: 0.025 | H23: 0.16
A24: find | B24: avl | C24: sorted | D24: 262144 | E24: 46.7 | F24: 21412588 | G24: 0.003 | H24: 0.11
A25: find | B25: avl | C25: random | D25: 262144 | E25: 55.55 | F25: 18002787 | G25: 0.055 | H25: 0.15 | I25: Yes
A26: insert | B26: map | C26: sorted | D26: 4096 | E26: 19.7 | F26: 50753370 | G26: 0.029 | H26: 0
A27: insert | B27: map | C27: random | D27: 4096 | E27: 55.18 | F27: 18122691 | G27: 0.009 | H27: 0
A28: insert | B28: rb | C28: sorted | D28: 4096 | E28: 21.81 | F28: 45851944 | G28: 0.011 | H28: 0
A29: insert | B29: rb | C29: random | D29: 4096 | E29: 36.62 | F29: 27308305 | G29: 0.023 | H29: 0
A30: insert | B30: avl | C30: sorted | D30: 4096 | E30: 23.48 | F30: 42587702 | G30: 0.041 | H30: 0
A31: insert | B31: avl | C31: random | D31: 4096 | E31: 62.28 | F31: 16057393 | G31: 0.024 | H31: 0
A32: insert | B32: map | C32: sorted | D32: 16384 | E32: 24.27 | F32: 41196053 | G32: 0.052 | H32: 0 | I32: Yes
A33: insert | B33: map | C33: random | D33: 16384 | E33: 76.13 | F33: 13135836 | G33: 0.038 | H33: 0.02
A34: insert | B34: rb | C34: sorted | D34: 16384 | E34: 62.25 | F34: 16064619 | G34: 0.176 | H34: 0.01 | I34: Yes
A35: insert | B35: rb | C35: random | D35: 16384 | E35: 101.74 | F35: 9828699.6 | G35: 0.056 | H35: 0.02 | I35: Yes
A36: insert | B36: avl | C36: sorted | D36: 16384 | E36: 25.75 | F36: 38828601 | G36: 0.053 | H36: 0 | I36: Yes
A37: insert | B37: avl | C37: random | D37: 16384 | E37: 87.43 | F37: 11437076 | G37: 0.018 | H37: 0.02
A38: insert | B38: map | C38: sorted | D38: 65536 | E38: 58.09 | F38: 17214980 | G38: 0.121 | H38: 0.04 | I38: Yes
A39: insert | B39: map | C39: random | D39: 65536 | E39: 97.21 | F39: 10287075 | G39: 0.013 | H39: 0.07
A40: insert | B40: rb | C40: sorted | D40: 65536 | E40: 81.01 | F40: 12343761 | G40: 0.033 | H40: 0.05
A41: insert | B41: rb | C41: random | D41: 65536 | E41: 103.28 | F41: 9682731.6 | G41: 0.05 | H41: 0.07
A42: insert | B42: avl | C42: sorted | D42: 65536 | E42: 30.37 | F42: 32929668 | G42: 0.023 | H42: 0.04
A43: insert | B43: avl | C43: random | D43: 65536 | E43: 111.05 | F43: 9005269.2 | G43: 0.007 | H43: 0.08
A44: insert | B44: map | C44: sorted | D44: 262144 | E44: 87.67 | F44: 11406565 | G44: 0.138 | H44: 0.23 | I44: Yes
A45: insert | B45: map | C45: random | D45: 262144 | E45: 172.95 | F45: 5781948.4 | G45: 0.04 | H45: 0.49
A46: insert | B46: rb | C46: sorted | D46: 262144 | E46: 93.62 | F46: 10681095 | G46: 0.057 | H46: 0.26 | I46: Yes
A47: insert | B47: rb | C47: random | D47: 262144 | E47: 253.56 | F47: 3943793 | G47: 0.164 | H47: 0.78 | I47: Yes
...

Sheet Run 6
A1: Operation | B1: Structure | C1: Order | D1: n | E1: ns/op | F1: ops/s | G1: Err % | H1: Total (s) | I1: Unstable
A2: find | B2: map | C2: sorted | D2: 4096 | E2: 49.55 | F2: 20182484 | G2: 0.017 | H2: 0.11
A3: find | B3: map | C3: random | D3: 4096 | E3: 40.23 | F3: 24857051 | G3: 0.01 | H3: 0.1
A4: find | B4: rb | C4: sorted | D4: 4096 | E4: 15.2 | F4: 65809906 | G4: 0.034 | H4: 0.04
A5: find | B5: rb | C5: random | D5: 4096 | E5: 11.26 | F5: 88795802 | G5: 0.005 | H5: 0.03
A6: find | B6: avl | C6: sorted | D6: 4096 | E6: 9.22 | F6: 1.0850437e+08 | G6: 0.021 | H6: 0.02
A7: find | B7: avl | C7: random | D7: 4096 | E7: 11.59 | F7: 86273534 | G7: 0.01 | H7: 0.03
A8: find | B8: map | C8: sorted | D8: 16384 | E8: 69.84 | F8: 14318261 | G8: 0.005 | H8: 0.15
A9: find | B9: map | C9: random | D9: 16384 | E9: 60.27 | F9: 16593259 | G9: 0.005 | H9: 0.15
A10: find | B10: rb | C10: sorted | D10: 16384 | E10: 26.49 | F10: 37756046 | G10: 0.008 | H10: 0.06
A11: find | B11: rb | C11: random | D11: 16384 | E11: 23.8 | F11: 42023062 | G11: 0.012 | H11: 0.06
A12: find | B12: avl | C12: sorted | D12: 16384 | E12: 17.46 | F12: 57260267 | G12: 0.005 | H12: 0.04
A13: find | B13: avl | C13: random | D13: 16384 | E13: 20.91 | F13: 47817710 | G13: 0.022 | H13: 0.05
... A33: insert | B33: map | C33: random | D33: 16384 | E33: 72.45 | F33: 13802795 | G33: 0.015 | H33: 0.01
A34: insert | B34: rb | C34: sorted | D34: 16384 | E34: 28.38 | F34: 35241305 | G34: 0.058 | H34: 0.01 | I34: Yes
A35: insert | B35: rb | C35: random | D35: 16384 | E35: 58.02 | F35: 17235539 | G35: 0.016 | H35: 0.01
A36: insert | B36: avl | C36: sorted | D36: 16384 | E36: 26.64 | F36: 37542506 | G36: 0.033 | H36: 0
A37: insert | B37: avl | C37: random | D37: 16384 | E37: 76.98 | F37: 12990226 | G37: 0.012 | H37: 0.01
A38: insert | B38: map | C38: sorted | D38: 65536 | E38: 56.94 | F38: 17561903 | G38: 0.032 | H38: 0.03
A39: insert | B39: map | C39: random | D39: 65536 | E39: 95.35 | F39: 10487806 | G39: 0.019 | H39: 0.07
A40: insert | B40: rb | C40: sorted | D40: 65536 | E40: 89.08 | F40: 11225883 | G40: 0.041 | H40: 0.05
A41: insert | B41: rb | C41: random | D41: 65536 | E41: 114.07 | F41: 8766823.1 | G41: 0.056 | H41: 0.08 | I41: Yes
A42: insert | B42: avl | C42: sorted | D42: 65536 | E42: 31.66 | F42: 31585061 | G42: 0.02 | H42: 0.04
A43: insert | B43: avl | C43: random | D43: 65536 | E43: 107.21 | F43: 9327908.4 | G43: 0.033 | H43: 0.08
A44: insert | B44: map | C44: sorted | D44: 262144 | E44: 77.17 | F44: 12959073 | G44: 0.159 | H44: 0.23 | I44: Yes
A45: insert | B45: map | C45: random | D45: 262144 | E45: 155.58 | F45: 6427734.2 | G45: 0.01 | H45: 0.45
A46: insert | B46: rb | C46: sorted | D46: 262144 | E46: 76.55 | F46: 13063201 | G46: 0.028 | H46: 0.22
A47: insert | B47: rb | C47: random | D47: 262144 | E47: 195.34 | F47: 5119388.3 | G47: 0.028 | H47: 0.56
A48: insert | B48: avl | C48: sorted | D48: 262144 | E48: 42.98 | F48: 23268831 | G48: 0.086 | H48: 0.23 | I48: Yes
A49: insert | B49: avl | C49: random | D49: 262144 | E49: 180.92 | F49: 5527369 | G49: 0.021 | H49: 0.53
A50: erase | B50: map | C50: sorted | D50: 4096 | E50: 17.52 | F50: 57079153 | G50: 0.013 | H50: 0
A51: erase | B51: map | C51: random | D51: 4096 | E51: 60.22 | F51: 16604508 | G51: 0.021 | H51: 0
A52: erase | B52: rb | C52: sorted | D52: 4096 | E52: 14.72 | F52: 67949569 | G52: 0.037 | H52: 0
A53: erase | B53: rb | C53: random | D53: 4096 | E53: 38.82 | F53: 25761492 | G53: 0.016 | H53: 0
A54: erase | B54: avl | C54: sorted | D54: 4096 | E54: 19.49 | F54: 51303890 | G54: 0.052 | H54: 0 | I54: Yes
A55: erase | B55: avl | C55: random | D55: 4096 | E55: 62.71 | F55: 15946678 | G55: 0.015 | H55: 0
A56: erase | B56: map | C56: sorted | D56: 16384 | E56: 18.91 | F56: 52894440 | G56: 0.066 | H56: 0 | I56: Yes
A57: erase | B57: map | C57: random | D57: 16384 | E57: 82.61 | F57: 12104350 | G57: 0.012 | H57: 0.01
A58: erase | B58: rb | C58: sorted | D58: 16384 | E58: 17.34 | F58: 57679580 | G58: 0.092 | H58: 0 | I58: Yes
A59: erase | B59: rb | C59: random | D59: 16384 | E59: 55.72 | F59: 17948401 | G59: 0.003 | H59: 0.01
...

Sheet Run 7
A1: Operation | B1: Structure | C1: Order | D1: n | E1: ns/op | F1: ops/s | G1: Err % | H1: Total (s) | I1: Unstable
A2: find | B2: map | C2: sorted | D2: 4096 | E2: 46.44 | F2: 21533254 | G2: 0.009 | H2: 0.11
A3: find | B3: map | C3: random | D3: 4096 | E3: 41.28 | F3: 24224854 | G3: 0.006 | H3: 0.1
A4: find | B4: rb | C4: sorted | D4: 4096 | E4: 14.62 | F4: 68407218 | G4: 0.01 | H4: 0.04
A5: find | B5: rb | C5: random | D5: 4096 | E5: 11.34 | F5: 88214590 | G5: 0.005 | H5: 0.03
A6: find | B6: avl | C6: sorted | D6: 4096 | E6: 9.63 | F6: 103852151 | G6: 0.024 | H6: 0.02
A7: find | B7: avl | C7: random | D7: 4096 | E7: 11.5 | F7: 86933823 | G7: 0.005 | H7: 0.03
A8: find | B8: map | C8: sorted | D8: 16384 | E8: 69.61 | F8: 14365933 | G8: 0.009 | H8: 0.15
A9: find | B9: map | C9: random | D9: 16384 | E9: 61.45 | F9: 16272294 | G9: 0.002 | H9: 0.15
A10: find | B10: rb | C10: sorted | D10: 16384 | E10: 26.62 | F10: 37566719 | G10: 0.002 | H10: 0.06
A11: find | B11: rb | C11: random | D11: 16384 | E11: 24.55 | F11: 40736472 | G11: 0.006 | H11: 0.06
A12: find | B12: avl | C12: sorted | D12: 16384 | E12: 18.1 | F12: 55240955 | G12: 0.006 | H12: 0.04
A13: find | B13: avl | C13: random | D13: 16384 | E13: 21.34 | F13: 46852951 | G13: 0.015 | H13: 0.05
... A37: insert | B37: avl | C37: random | D37: 16384 | E37: 79.23 | F37: 12621699 | G37: 0.004 | H37: 0.01
A38: insert | B38: map | C38: sorted | D38: 65536 | E38: 57.23 | F38: 17473653 | G38: 0.051 | H38: 0.03 | I38: Yes
A39: insert | B39: map | C39: random | D39: 65536 | E39: 95.19 | F39: 10505854 | G39: 0.009 | H39: 0.07
A40: insert | B40: rb | C40: sorted | D40: 65536 | E40: 54.9 | F40: 18214498 | G40: 0.245 | H40: 0.04 | I40: Yes
A41: insert | B41: rb | C41: random | D41: 65536 | E41: 97.49 | F41: 10257813 | G41: 0.054 | H41: 0.07 | I41: Yes
A42: insert | B42: avl | C42: sorted | D42: 65536 | E42: 31.92 | F42: 31325912 | G42: 0.045 | H42: 0.04
A43: insert | B43: avl | C43: random | D43: 65536 | E43: 111.24 | F43: 8989706.1 | G43: 0.017 | H43: 0.08
A44: insert | B44: map | C44: sorted | D44: 262144 | E44: 81.36 | F44: 12290834 | G44: 0.097 | H44: 0.22 | I44: Yes
A45: insert | B45: map | C45: random | D45: 262144 | E45: 157.65 | F45: 6343042.1 | G45: 0.014 | H45: 0.45
A46: insert | B46: rb | C46: sorted | D46: 262144 | E46: 75.06 | F46: 13321944 | G46: 0.016 | H46: 0.22
A47: insert | B47: rb | C47: random | D47: 262144 | E47: 191.79 | F47: 5213966.8 | G47: 0.019 | H47: 0.55
A48: insert | B48: avl | C48: sorted | D48: 262144 | E48: 41.83 | F48: 23903871 | G48: 0.028 | H48: 0.22
A49: insert | B49: avl | C49: random | D49: 262144 | E49: 175.96 | F49: 5683000.2 | G49: 0.01 | H49: 0.51
A50: erase | B50: map | C50: sorted | D50: 4096 | E50: 16.58 | F50: 60302691 | G50: 0.012 | H50: 0
A51: erase | B51: map | C51: random | D51: 4096 | E51: 56.95 | F51: 17560256 | G51: 0.011 | H51: 0
A52: erase | B52: rb | C52: sorted | D52: 4096 | E52: 14.07 | F52: 71065461 | G52: 0.017 | H52: 0
A53: erase | B53: rb | C53: random | D53: 4096 | E53: 36.74 | F53: 27215043 | G53: 0.02 | H53: 0
A54: erase | B54: avl | C54: sorted | D54: 4096 | E54: 18.82 | F54: 53132702 | G54: 0.092 | H54: 0 | I54: Yes
A55: erase | B55: avl | C55: random | D55: 4096 | E55: 59.07 | F55: 16929747 | G55: 0.024 | H55: 0
A56: erase | B56: map | C56: sorted | D56: 16384 | E56: 18.01 | F56: 55539736 | G56: 0.05 | H56: 0
A57: erase | B57: map | C57: random | D57: 16384 | E57: 79.12 | F57: 12639352 | G57: 0.014 | H57: 0.01
A58: erase | B58: rb | C58: sorted | D58: 16384 | E58: 18.46 | F58: 54157687 | G58: 0.052 | H58: 0 | I58: Yes
A59: erase | B59: rb | C59: random | D59: 16384 | E59: 52.2 | F59: 19156031 | G59: 0.014 | H59: 0.01
A60: erase | B60: avl | C60: sorted | D60: 16384 | E60: 23.45 | F60: 42650451 | G60: 0.028 | H60: 0
A61: erase | B61: avl | C61: random | D61: 16384 | E61: 79.63 | F61: 12558696 | G61: 0.015 | H61: 0.01
A62: erase | B62: map | C62: sorted | D62: 65536 | E62: 19.13 | F62: 52267023 | G62: 0.017 | H62: 0.01
A63: erase | B63: map | C63: random | D63: 65536 | E63: 117.82 | F63: 8487198.6 | G63: 0.008 | H63: 0.09
...

Sheet Run 8
A1: Operation | B1: Structure | C1: Order | D1: n | E1: ns/op | F1: ops/s | G1: Err % | H1: Total (s) | I1: Unstable
A2: find | B2: map | C2: sorted | D2: 4096 | E2: 46.63 | F2: 21445871 | G2: 0.009 | H2: 0.11
A3: find | B3: map | C3: random | D3: 4096 | E3: 42.06 | F3: 23773862 | G3: 0.009 | H3: 0.1
A4: find | B4: rb | C4: sorted | D4: 4096 | E4: 14.84 | F4: 67393026 | G4: 0.006 | H4: 0.04
A5: find | B5: rb | C5: random | D5: 4096 | E5: 12.94 | F5: 77293143 | G5: 0.01 | H5: 0.03
A6: find | B6: avl | C6: sorted | D6: 4096 | E6: 9.43 | F6: 1.0605681e+08 | G6: 0.005 | H6: 0.02
A7: find | B7: avl | C7: random | D7: 4096 | E7: 11.71 | F7: 85418362 | G7: 0.008 | H7: 0.03
A8: find | B8: map | C8: sorted | D8: 16384 | E8: 68.81 | F8: 14531875 | G8: 0.011 | H8: 0.15
A9: find | B9: map | C9: random | D9: 16384 | E9: 62.08 | F9: 16107150 | G9: 0.011 | H9: 0.15
A10: find | B10: rb | C10: sorted | D10: 16384 | E10: 26.23 | F10: 38117167 | G10: 0.013 | H10: 0.06
A11: find | B11: rb | C11: random | D11: 16384 | E11: 23.82 | F11: 41978660 | G11: 0.011 | H11: 0.06
A12: find | B12: avl | C12: sorted | D12: 16384 | E12: 17.82 | F12: 56111411 | G12: 0.003 | H12: 0.04
A13: find | B13: avl | C13: random | D13: 16384 | E13: 21.04 | F13: 47522894 | G13: 0.01 | H13: 0.05
... A28: insert | B28: rb | C28: sorted | D28: 4096 | E28: 22.08 | F28: 45280182 | G28: 0.027 | H28: 0
A29: insert | B29: rb | C29: random | D29: 4096 | E29: 40.47 | F29: 24711617 | G29: 0.077 | H29: 0 | I29: Yes
A30: insert | B30: avl | C30: sorted | D30: 4096 | E30: 22.85 | F30: 43762086 | G30: 0.03 | H30: 0
A31: insert | B31: avl | C31: random | D31: 4096 | E31: 60.87 | F31: 16428291 | G31: 0.015 | H31: 0
A32: insert | B32: map | C32: sorted | D32: 16384 | E32: 24.8 | F32: 40327364 | G32: 0.054 | H32: 0 | I32: Yes
A33: insert | B33: map | C33: random | D33: 16384 | E33: 72.94 | F33: 13709003 | G33: 0.017 | H33: 0.01
A34: insert | B34: rb | C34: sorted | D34: 16384 | E34: 29.22 | F34: 34226458 | G34: 0.048 | H34: 0.01
A35: insert | B35: rb | C35: random | D35: 16384 | E35: 57.67 | F35: 17338850 | G35: 0.025 | H35: 0.01
A36: insert | B36: avl | C36: sorted | D36: 16384 | E36: 25.92 | F36: 38575549 | G36: 0.019 | H36: 0
A37: insert | B37: avl | C37: random | D37: 16384 | E37: 78.66 | F37: 12713666 | G37: 0.007 | H37: 0.01
A38: insert | B38: map | C38: sorted | D38: 65536 | E38: 58.14 | F38: 17199082 | G38: 0.014 | H38: 0.03
A39: insert | B39: map | C39: random | D39: 65536 | E39: 96.39 | F39: 10374505 | G39: 0.011 | H39: 0.07
A40: insert | B40: rb | C40: sorted | D40: 65536 | E40: 50.42 | F40: 19835357 | G40: 0.24 | H40: 0.04 | I40: Yes
A41: insert | B41: rb | C41: random | D41: 65536 | E41: 94.14 | F41: 10621995 | G41: 0.105 | H41: 0.07 | I41: Yes
A42: insert | B42: avl | C42: sorted | D42: 65536 | E42: 30.98 | F42: 32278369 | G42: 0.026 | H42: 0.04
A43: insert | B43: avl | C43: random | D43: 65536 | E43: 109.05 | F43: 9170282.3 | G43: 0.022 | H43: 0.08
A44: insert | B44: map | C44: sorted | D44: 262144 | E44: 77.6 | F44: 12886995 | G44: 0.143 | H44: 0.22 | I44: Yes
A45: insert | B45: map | C45: random | D45: 262144 | E45: 156.36 | F45: 6395476 | G45: 0.008 | H45: 0.45
A46: insert | B46: rb | C46: sorted | D46: 262144 | E46: 79.69 | F46: 12548066 | G46: 0.073 | H46: 0.23 | I46: Yes
A47: insert | B47: rb | C47: random | D47: 262144 | E47: 195.35 | F47: 5118980.4 | G47: 0.036 | H47: 0.56
A48: insert | B48: avl | C48: sorted | D48: 262144 | E48: 43.18 | F48: 23160202 | G48: 0.086 | H48: 0.22 | I48: Yes
A49: insert | B49: avl | C49: random | D49: 262144 | E49: 181.49 | F49: 5509944.5 | G49: 0.01 | H49: 0.52
A50: erase | B50: map | C50: sorted | D50: 4096 | E50: 17.61 | F50: 56801320 | G50: 0.025 | H50: 0
A51: erase | B51: map | C51: random | D51: 4096 | E51: 60.82 | F51: 16442535 | G51: 0.02 | H51: 0
A52: erase | B52: rb | C52: sorted | D52: 4096 | E52: 15.33 | F52: 65214622 | G52: 0.072 | H52: 0 | I52: Yes
A53: erase | B53: rb | C53: random | D53: 4096 | E53: 38.79 | F53: 25783060 | G53: 0.011 | H53: 0
A54: erase | B54: avl | C54: sorted | D54: 4096 | E54: 19.98 | F54: 50042761 | G54: 0.04 | H54: 0
...

Sheet Run 9
A1: Operation | B1: Structure | C1: Order | D1: n | E1: ns/op | F1: ops/s | G1: Err % | H1: Total (s) | I1: Unstable
A2: find | B2: map | C2: sorted | D2: 4096 | E2: 47.71 | F2: 20959248 | G2: 0.006 | H2: 0.12
A3: find | B3: map | C3: random | D3: 4096 | E3: 39.52 | F3: 25301779 | G3: 0.007 | H3: 0.1
A4: find | B4: rb | C4: sorted | D4: 4096 | E4: 15.04 | F4: 66470613 | G4: 0.007 | H4: 0.04
A5: find | B5: rb | C5: random | D5: 4096 | E5: 12.13 | F5: 82466389 | G5: 0.007 | H5: 0.03
A6: find | B6: avl | C6: sorted | D6: 4096 | E6: 9.63 | F6: 1.0388695e+08 | G6: 0.009 | H6: 0.02
A7: find | B7: avl | C7: random | D7: 4096 | E7: 11.63 | F7: 85953241 | G7: 0.005 | H7: 0.03
A8: find | B8: map | C8: sorted | D8: 16384 | E8: 69.22 | F8: 14446353 | G8: 0.003 | H8: 0.15
A9: find | B9: map | C9: random | D9: 16384 | E9: 61.5 | F9: 16258922 | G9: 0.004 | H9: 0.15
A10: find | B10: rb | C10: sorted | D10: 16384 | E10: 26.58 | F10: 37624739 | G10: 0.005 | H10: 0.07
A11: find | B11: rb | C11: random | D11: 16384 | E11: 24.18 | F11: 41348178 | G11: 0.013 | H11: 0.06
A12: find | B12: avl | C12: sorted | D12: 16384 | E12: 17.98 | F12: 55630182 | G12: 0.009 | H12: 0.04
A13: find | B13: avl | C13: random | D13: 16384 | E13: 21.2 | F13: 47176359 | G13: 0.009 | H13: 0.05
... A20: find | B20: map | C20: sorted | D20: 262144 | E20: 189.14 | F20: 5287198.7 | G20: 0.009 | H20: 0.46
A21: find | B21: map | C21: random | D21: 262144 | E21: 212.16 | F21: 4713512.5 | G21: 0.141 | H21: 0.53 | I21: Yes
A22: find | B22: rb | C22: sorted | D22: 262144 | E22: 80.09 | F22: 12486317 | G22: 0.009 | H22: 0.2
A23: find | B23: rb | C23: random | D23: 262144 | E23: 74.36 | F23: 13448690 | G23: 0.01 | H23: 0.18
A24: find | B24: avl | C24: sorted | D24: 262144 | E24: 49.74 | F24: 20104022 | G24: 0.01 | H24: 0.12
A25: find | B25: avl | C25: random | D25: 262144 | E25: 53.32 | F25: 18753467 | G25: 0.033 | H25: 0.13
A26: insert | B26: map | C26: sorted | D26: 4096 | E26: 20.05 | F26: 49866082 | G26: 0.025 | H26: 0
A27: insert | B27: map | C27: random | D27: 4096 | E27: 56.63 | F27: 17658445 | G27: 0.013 | H27: 0
A28: insert | B28: rb | C28: sorted | D28: 4096 | E28: 22.55 | F28: 44353005 | G28: 0.021 | H28: 0
A29: insert | B29: rb | C29: random | D29: 4096 | E29: 38.24 | F29: 26153807 | G29: 0.043 | H29: 0
A30: insert | B30: avl | C30: sorted | D30: 4096 | E30: 24.53 | F30: 40767983 | G30: 0.021 | H30: 0
A31: insert | B31: avl | C31: random | D31: 4096 | E31: 59.82 | F31: 16715706 | G31: 0.021 | H31: 0
A32: insert | B32: map | C32: sorted | D32: 16384 | E32: 23.86 | F32: 41905707 | G32: 0.102 | H32: 0 | I32: Yes
A33: insert | B33: map | C33: random | D33: 16384 | E33: 72.88 | F33: 13721162 | G33: 0.01 | H33: 0.01
A34: insert | B34: rb | C34: sorted | D34: 16384 | E34: 61.03 | F34: 16384918 | G34: 0.127 | H34: 0.01 | I34: Yes
A35: insert | B35: rb | C35: random | D35: 16384 | E35: 86.63 | F35: 11543336 | G35: 0.21 | H35: 0.02 | I35: Yes
A36: insert | B36: avl | C36: sorted | D36: 16384 | E36: 27.38 | F36: 36520479 | G36: 0.059 | H36: 0 | I36: Yes
A37: insert | B37: avl | C37: random | D37: 16384 | E37: 88.27 | F37: 11329470 | G37: 0.022 | H37: 0.02
A38: insert | B38: map | C38: sorted | D38: 65536 | E38: 60.17 | F38: 16620358 | G38: 0.022 | H38: 0.04
A39: insert | B39: map | C39: random | D39: 65536 | E39: 98.51 | F39: 10151647 | G39: 0.01 | H39: 0.07
A40: insert | B40: rb | C40: sorted | D40: 65536 | E40: 69.64 | F40: 14358947 | G40: 0.126 | H40: 0.04 | I40: Yes
A41: insert | B41: rb | C41: random | D41: 65536 | E41: 105.95 | F41: 9438686.5 | G41: 0.057 | H41: 0.08 | I41: Yes
A42: insert | B42: avl | C42: sorted | D42: 65536 | E42: 31.82 | F42: 31423860 | G42: 0.045 | H42: 0.04
A43: insert | B43: avl | C43: random | D43: 65536 | E43: 110.63 | F43: 9038760.1 | G43: 0.014 | H43: 0.08
A44: insert | B44: map | C44: sorted | D44: 262144 | E44: 77.07 | F44: 12975093 | G44: 0.173 | H44: 0.22 | I44: Yes
A45: insert | B45: map | C45: random | D45: 262144 | E45: 157.02 | F45: 6368530.5 | G45: 0.012 | H45: 0.45
A46: insert | B46: rb | C46: sorted | D46: 262144 | E46: 89.2 | F46: 11210151 | G46: 0.017 | H46: 0.25
...

Sheet Run 10
A1: Operation | B1: Structure | C1: Order | D1: n | E1: ns/op | F1: ops/s | G1: Err % | H1: Total (s) | I1: Unstable
A2: find | B2: map | C2: sorted | D2: 4096 | E2: 46.3 | F2: 21597370 | G2: 0.011 | H2: 0.11
A3: find | B3: map | C3: random | D3: 4096 | E3: 41.09 | F3: 24336274 | G3: 0.006 | H3: 0.1
A4: find | B4: rb | C4: sorted | D4: 4096 | E4: 13.57 | F4: 73686045 | G4: 0.005 | H4: 0.03
A5: find | B5: rb | C5: random | D5: 4096 | E5: 12.61 | F5: 79316816 | G5: 0.004 | H5: 0.03
A6: find | B6: avl | C6: sorted | D6: 4096 | E6: 9.4 | F6: 1.06345e+08 | G6: 0.009 | H6: 0.02
A7: find | B7: avl | C7: random | D7: 4096 | E7: 11.94 | F7: 83781274 | G7: 0.011 | H7: 0.03
A8: find | B8: map | C8: sorted | D8: 16384 | E8: 68.69 | F8: 14558447 | G8: 0.007 | H8: 0.15
A9: find | B9: map | C9: random | D9: 16384 | E9: 61.04 | F9: 16382238 | G9: 0.003 | H9: 0.15
A10: find | B10: rb | C10: sorted | D10: 16384 | E10: 26.75 | F10: 37386120 | G10: 0.004 | H10: 0.06
A11: find | B11: rb | C11: random | D11: 16384 | E11: 24.05 | F11: 41586202 | G11: 0.007 | H11: 0.06
A12: find | B12: avl | C12: sorted | D12: 16384 | E12: 17.76 | F12: 56305102 | G12: 0.006 | H12: 0.04
A13: find | B13: avl | C13: random | D13: 16384 | E13: 20.91 | F13: 47817333 | G13: 0.025 | H13: 0.05
... A31: insert | B31: avl | C31: random | D31: 4096 | E31: 59.48 | F31: 16812379 | G31: 0.009 | H31: 0
A32: insert | B32: map | C32: sorted | D32: 16384 | E32: 23.27 | F32: 42978146 | G32: 0.076 | H32: 0 | I32: Yes
A33: insert | B33: map | C33: random | D33: 16384 | E33: 69.93 | F33: 14300053 | G33: 0.017 | H33: 0.01
A34: insert | B34: rb | C34: sorted | D34: 16384 | E34: 28.84 | F34: 34675940 | G34: 0.045 | H34: 0.01
A35: insert | B35: rb | C35: random | D35: 16384 | E35: 56.59 | F35: 17669986 | G35: 0.007 | H35: 0.01
A36: insert | B36: avl | C36: sorted | D36: 16384 | E36: 25.91 | F36: 38599632 | G36: 0.044 | H36: 0
A37: insert | B37: avl | C37: random | D37: 16384 | E37: 75.96 | F37: 13164460 | G37: 0.015 | H37: 0.01
A38: insert | B38: map | C38: sorted | D38: 65536 | E38: 56.17 | F38: 17803127 | G38: 0.104 | H38: 0.03 | I38: Yes
A39: insert | B39: map | C39: random | D39: 65536 | E39: 92.32 | F39: 10832307 | G39: 0.017 | H39: 0.07
A40: insert | B40: rb | C40: sorted | D40: 65536 | E40: 80.09 | F40: 12486154 | G40: 0.083 | H40: 0.05 | I40: Yes
A41: insert | B41: rb | C41: random | D41: 65536 | E41: 95.26 | F41: 10497420 | G41: 0.073 | H41: 0.07 | I41: Yes
A42: insert | B42: avl | C42: sorted | D42: 65536 | E42: 31.52 | F42: 31726084 | G42: 0.032 | H42: 0.04
A43: insert | B43: avl | C43: random | D43: 65536 | E43: 106.48 | F43: 9391816.3 | G43: 0.013 | H43: 0.08
A44: insert | B44: map | C44: sorted | D44: 262144 | E44: 73.86 | F44: 13538640 | G44: 0.137 | H44: 0.22 | I44: Yes
A45: insert | B45: map | C45: random | D45: 262144 | E45: 147.42 | F45: 6783366.2 | G45: 0.004 | H45: 0.43
A46: insert | B46: rb | C46: sorted | D46: 262144 | E46: 75.49 | F46: 13247568 | G46: 0.019 | H46: 0.21
A47: insert | B47: rb | C47: random | D47: 262144 | E47: 189.97 | F47: 5264052 | G47: 0.016 | H47: 0.54
A48: insert | B48: avl | C48: sorted | D48: 262144 | E48: 41.28 | F48: 24225732 | G48: 0.044 | H48: 0.21
A49: insert | B49: avl | C49: random | D49: 262144 | E49: 175.02 | F49: 5713740.1 | G49: 0.014 | H49: 0.51
A50: erase | B50: map | C50: sorted | D50: 4096 | E50: 17.5 | F50: 57158008 | G50: 0.016 | H50: 0
A51: erase | B51: map | C51: random | D51: 4096 | E51: 58.46 | F51: 17104439 | G51: 0.022 | H51: 0
A52: erase | B52: rb | C52: sorted | D52: 4096 | E52: 14.74 | F52: 67841526 | G52: 0.069 | H52: 0 | I52: Yes
A53: erase | B53: rb | C53: random | D53: 4096 | E53: 38.29 | F53: 26115287 | G53: 0.029 | H53: 0
A54: erase | B54: avl | C54: sorted | D54: 4096 | E54: 19.4 | F54: 51559628 | G54: 0.013 | H54: 0
A55: erase | B55: avl | C55: random | D55: 4096 | E55: 61.66 | F55: 16217864 | G55: 0.037 | H55: 0
A56: erase | B56: map | C56: sorted | D56: 16384 | E56: 17.92 | F56: 55793933 | G56: 0.064 | H56: 0 | I56: Yes
A57: erase | B57: map | C57: random | D57: 16384 | E57: 80.82 | F57: 12372959 | G57: 0.007 | H57: 0.01
...

Sheet Run 11
A1: Operation | B1: Structure | C1: Order | D1: n | E1: ns/op | F1: ops/s | G1: Err % | H1: Total (s) | I1: Unstable
A2: find | B2: map | C2: sorted | D2: 4096 | E2: 46.78 | F2: 21375212 | G2: 0.005 | H2: 0.11
A3: find | B3: map | C3: random | D3: 4096 | E3: 41.05 | F3: 24361692 | G3: 0.003 | H3: 0.1
A4: find | B4: rb | C4: sorted | D4: 4096 | E4: 14.82 | F4: 67474867 | G4: 0.007 | H4: 0.04
A5: find | B5: rb | C5: random | D5: 4096 | E5: 12.44 | F5: 80411287 | G5: 0.011 | H5: 0.03
A6: find | B6: avl | C6: sorted | D6: 4096 | E6: 9.53 | F6: 1.0488031e+08 | G6: 0.008 | H6: 0.02
A7: find | B7: avl | C7: random | D7: 4096 | E7: 11.37 | F7: 87924188 | G7: 0.008 | H7: 0.03
A8: find | B8: map | C8: sorted | D8: 16384 | E8: 68.05 | F8: 14695442 | G8: 0.012 | H8: 0.15
A9: find | B9: map | C9: random | D9: 16384 | E9: 59.99 | F9: 16668965 | G9: 0.011 | H9: 0.15
A10: find | B10: rb | C10: sorted | D10: 16384 | E10: 26.19 | F10: 38187131 | G10: 0.005 | H10: 0.06
A11: find | B11: rb | C11: random | D11: 16384 | E11: 24.19 | F11: 41335701 | G11: 0.01 | H11: 0.06
A12: find | B12: avl | C12: sorted | D12: 16384 | E12: 18 | F12: 55552780 | G12: 0.009 | H12: 0.04
A13: find | B13: avl | C13: random | D13: 16384 | E13: 21.22 | F13: 47122178 | G13: 0.006 | H13: 0.05
... A31: insert | B31: avl | C31: random | D31: 4096 | E31: 59.91 | F31: 16690844 | G31: 0.025 | H31: 0
A32: insert | B32: map | C32: sorted | D32: 16384 | E32: 24.74 | F32: 40417795 | G32: 0.069 | H32: 0 | I32: Yes
A33: insert | B33: map | C33: random | D33: 16384 | E33: 71.86 | F33: 13915360 | G33: 0.017 | H33: 0.01
A34: insert | B34: rb | C34: sorted | D34: 16384 | E34: 28.48 | F34: 35106440 | G34: 0.026 | H34: 0.01
A35: insert | B35: rb | C35: random | D35: 16384 | E35: 56.88 | F35: 17581248 | G35: 0.009 | H35: 0.01
A36: insert | B36: avl | C36: sorted | D36: 16384 | E36: 25.72 | F36: 38887768 | G36: 0.031 | H36: 0
A37: insert | B37: avl | C37: random | D37: 16384 | E37: 75.91 | F37: 13173817 | G37: 0.009 | H37: 0.01
A38: insert | B38: map | C38: sorted | D38: 65536 | E38: 56.4 | F38: 17729083 | G38: 0.045 | H38: 0.03
A39: insert | B39: map | C39: random | D39: 65536 | E39: 94.87 | F39: 10541025 | G39: 0.02 | H39: 0.07
A40: insert | B40: rb | C40: sorted | D40: 65536 | E40: 71.89 | F40: 13909343 | G40: 0.253 | H40: 0.05 | I40: Yes
A41: insert | B41: rb | C41: random | D41: 65536 | E41: 102.77 | F41: 9730292.3 | G41: 0.048 | H41: 0.07
A42: insert | B42: avl | C42: sorted | D42: 65536 | E42: 31.47 | F42: 31776217 | G42: 0.033 | H42: 0.04
A43: insert | B43: avl | C43: random | D43: 65536 | E43: 106.47 | F43: 9392397.7 | G43: 0.035 | H43: 0.08
A44: insert | B44: map | C44: sorted | D44: 262144 | E44: 76.15 | F44: 13132369 | G44: 0.193 | H44: 0.22 | I44: Yes
A45: insert | B45: map | C45: random | D45: 262144 | E45: 152.81 | F45: 6544017.1 | G45: 0.022 | H45: 0.44
A46: insert | B46: rb | C46: sorted | D46: 262144 | E46: 80.4 | F46: 12438149 | G46: 0.047 | H46: 0.24
A47: insert | B47: rb | C47: random | D47: 262144 | E47: 189.65 | F47: 5272950.5 | G47: 0.009 | H47: 0.54
A48: insert | B48: avl | C48: sorted | D48: 262144 | E48: 40.72 | F48: 24559863 | G48: 0.033 | H48: 0.22
A49: insert | B49: avl | C49: random | D49: 262144 | E49: 177.26 | F49: 5641552.5 | G49: 0.005 | H49: 0.51
A50: erase | B50: map | C50: sorted | D50: 4096 | E50: 17.5 | F50: 57142060 | G50: 0.037 | H50: 0
A51: erase | B51: map | C51: random | D51: 4096 | E51: 59.08 | F51: 16927438 | G51: 0.024 | H51: 0
A52: erase | B52: rb | C52: sorted | D52: 4096 | E52: 13.89 | F52: 71982145 | G52: 0.022 | H52: 0
A53: erase | B53: rb | C53: random | D53: 4096 | E53: 39.21 | F53: 25503882 | G53: 0.016 | H53: 0
A54: erase | B54: avl | C54: sorted | D54: 4096 | E54: 19.5 | F54: 51285904 | G54: 0.086 | H54: 0 | I54: Yes
A55: erase | B55: avl | C55: random | D55: 4096 | E55: 59.16 | F55: 16904733 | G55: 0.027 | H55: 0
A56: erase | B56: map | C56: sorted | D56: 16384 | E56: 18.39 | F56: 54388166 | G56: 0.059 | H56: 0 | I56: Yes
A57: erase | B57: map | C57: random | D57: 16384 | E57: 80.66 | F57: 12397423 | G57: 0.017 | H57: 0.01
...
